Workbook

Sheet README
B1: A TINY LLM IN A SPREADSHEET
B2: A complete, working next-word predictor trained on Alice in Wonderland. No macros, no add-ins, just formulas.
B4: WHAT THIS IS
B5: This workbook contains a real (very small) language model. It was trained with gradient descent on every
B6: pair of consecutive words in Alice in Wonderland, and its learned weights are baked into these tabs.
B7: You type up to three words on the Prompt tab and the sheet computes, live, the same pipeline a large
B8: language model uses: tokenize, embed, attend, transform, score every word, softmax, predict.
B10: HOW TO USE IT
B11: 1. Open the Prompt tab. The yellow cells are the only cells you need to touch.
B12: 2. Type words in the three yellow prompt cells. The last word matters most.
B13: 3. Watch every intermediate step update, and read the prediction at the bottom.
B14: 4. Try the attention scores and the temperature cell to change how the model behaves.
... B38: This is the same math that runs the largest models, shrunk until it fits in a workbook.

Sheet Prompt
B1: A TINY LLM: TYPE WORDS, WATCH IT THINK
B2: Only yellow cells are inputs. Everything else recomputes instantly. Read top to bottom.
B4: STEP 1 · YOUR PROMPT (up to 3 words; the last one matters most)
B5: word 1 (oldest) | C5: word 2 | D5: word 3 (most recent)
B6: off | C6: with | D6: her
B7: Type any words. A word the book never uses becomes token 1, <unk>, and is simply ignored.
B9: STEP 2 · TOKENIZE (find each word in the Vocabulary tab)
B10: =TRIM(SUBSTITUTE(SUBSTITUTE(SUBSTITUTE(SUBSTITUTE(LOWER(B6),".",""),",",""),"!",""),"?","")) -> off | C10: =TRIM(SUBSTITUTE(SUBSTITUTE(SUBSTITUTE(SUBSTITUTE(LOWER(C6),".",""),",",""),"!",""),"?","")) -> with | D10: =TRIM(SUBSTITUTE(SUBSTITUTE(SUBSTITUTE(SUBSTITUTE(LOWER(D6),".",""),",",""),"!",""),"?","")) -> her | E10: <- cleaned text (lowercased, punctuation stripped)
B11: =IFERROR(MATCH(B10,Vocabulary!$B$2:$B$2629,0),1) -> 59 | C11: =IFERROR(MATCH(C10,Vocabulary!$B$2:$B$2629,0),1) -> 21 | D11: =IFERROR(MATCH(D10,Vocabulary!$B$2:$B$2629,0),1) -> 17 | E11: <- token ID = row number in the Vocabulary tab (MATCH)
B12: =IF(ISNUMBER(MATCH(B10,Vocabulary!$B$2:$B$2629,0)),"in vocabulary","unknown, use <unk>") -> in vocabulary | C12: =IF(ISNUMBER(MATCH(C10,Vocabulary!$B$2:$B$2629,0)),"in vocabulary","unknown, use <unk>") -> in vocabulary | D12: =IF(ISNUMBER(MATCH(D10,Vocabulary!$B$2:$B$2629,0)),"in vocabulary","unknown, use <unk>") -> in vocabulary
B13: Full walk-through on the Tokenizer tab. All 2628 tokens are on the Vocabulary tab.
B15: STEP 3 · EMBEDDINGS (each token ID looks up its own row of 16 learned numbers)
B16: token | C16: d1 | D16: d2 | E16: d3 | F16: d4 | G16: d5 | H16: d6 | I16: d7 | J16: d8 | K16: d9 | L16: d10 | M16: d11 | N16: d12 | O16: d13 | P16: d14 | Q16: d15 | R16: d16
B17: =B10 -> off | C17: =INDEX(Embeddings!$C$2:$R$2629,$B$11,COLUMN()-2) -> -0.30472 | D17: =INDEX(Embeddings!$C$2:$R$2629,$B$11,COLUMN()-2) -> 0.1072 | E17: =INDEX(Embeddings!$C$2:$R$2629,$B$11,COLUMN()-2) -> 0.22908 | F17: =INDEX(Embeddings!$C$2:$R$2629,$B$11,COLUMN()-2) -> 0.08041 | G17: =INDEX(Embeddings!$C$2:$R$2629,$B$11,COLUMN()-2) -> -0.22041 | H17: =INDEX(Embeddings!$C$2:$R$2629,$B$11,COLUMN()-2) -> 0.52469 | I17: =INDEX(Embeddings!$C$2:$R$2629,$B$11,COLUMN()-2) -> 0.09208 | J17: =INDEX(Embeddings!$C$2:$R$2629,$B$11,COLUMN()-2) -> -0.45345 | ... R17: =INDEX(Embeddings!$C$2:$R$2629,$B$11,COLUMN()-2) -> 0.14106
B18: =C10 -> with | C18: =INDEX(Embeddings!$C$2:$R$2629,$C$11,COLUMN()-2) -> 0.17406 | D18: =INDEX(Embeddings!$C$2:$R$2629,$C$11,COLUMN()-2) -> -0.79726 | E18: =INDEX(Embeddings!$C$2:$R$2629,$C$11,COLUMN()-2) -> -0.28742 | F18: =INDEX(Embeddings!$C$2:$R$2629,$C$11,COLUMN()-2) -> 0.33556 | G18: =INDEX(Embeddings!$C$2:$R$2629,$C$11,COLUMN()-2) -> -0.43709 | H18: =INDEX(Embeddings!$C$2:$R$2629,$C$11,COLUMN()-2) -> -0.76418 | I18: =INDEX(Embeddings!$C$2:$R$2629,$C$11,COLUMN()-2) -> 0.40504 | J18: =INDEX(Embeddings!$C$2:$R$2629,$C$11,COLUMN()-2) -> 0.14907 | ... R18: =INDEX(Embeddings!$C$2:$R$2629,$C$11,COLUMN()-2) -> -0.69432
B19: =D10 -> her | C19: =INDEX(Embeddings!$C$2:$R$2629,$D$11,COLUMN()-2) -> 0.01907 | D19: =INDEX(Embeddings!$C$2:$R$2629,$D$11,COLUMN()-2) -> -0.81169 | E19: =INDEX(Embeddings!$C$2:$R$2629,$D$11,COLUMN()-2) -> -0.08415 | F19: =INDEX(Embeddings!$C$2:$R$2629,$D$11,COLUMN()-2) -> 0.08069 | G19: =INDEX(Embeddings!$C$2:$R$2629,$D$11,COLUMN()-2) -> 0.2302 | H19: =INDEX(Embeddings!$C$2:$R$2629,$D$11,COLUMN()-2) -> -0.22039 | I19: =INDEX(Embeddings!$C$2:$R$2629,$D$11,COLUMN()-2) -> -0.37581 | J19: =INDEX(Embeddings!$C$2:$R$2629,$D$11,COLUMN()-2) -> -0.83645 | ... R19: =INDEX(Embeddings!$C$2:$R$2629,$D$11,COLUMN()-2) -> -0.37579
B20: These 16-number vectors are the learned "meaning" of each word. Similar words get similar rows.
B22: STEP 4 · ATTENTION (how much should each word count?)
B23: 0 | C23: 1 | D23: 4 | E23: <- raw attention scores (editable)
B24: =EXP(B23)/(EXP($B$23)+EXP($C$23)+EXP($D$23)) -> 0.017147826 | C24: =EXP(C23)/(EXP($B$23)+EXP($C$23)+EXP($D$23)) -> 0.046612623 | D24: =EXP(D23)/(EXP($B$23)+EXP($C$23)+EXP($D$23)) -> 0.93623955 | E24: <- softmax of the scores: positive weights that sum to 100%
B25: The model was trained to predict from the most recent word, so the default puts ~94% there. Move the weight and watch quality drop.
B27: STEP 5 · MIX INTO ONE CONTEXT VECTOR (MMULT #1: 1x3 times 3x16 = 1x16)
B28: context c = | C28: {=MMULT(B24:D24,C17:R19)} -> 0.020742196 | D28: -0.79526041 | E28: -0.088253734 | F28: 0.092565358 | G28: 0.19136888 | H28: -0.23296098 | I28: -0.33138924 | J28: -0.78394471 | K28: 0.67495734 | L28: 0.15731405 | M28: -0.18527049 | N28: 0.47008748 | O28: 0.06501758 | P28: 0.56785946 | Q28: 0.19768907 | R28: -0.38177467
B30: STEP 6 · HIDDEN LAYER (MMULT #2: c times the 16x16 weight matrix, then TANH)
B31: c x W = | C31: {=MMULT(C28:R28,'Hidden Weights'!$C$3:$R$18)} -> 0.29218169 | D31: -0.032721335 | E31: -0.47905699 | F31: -1.2975455 | G31: 0.46988944 | H31: -0.94952619 | I31: -0.17383197 | J31: -0.45938902 | K31: -0.87348702 | L31: 0.6775371 | M31: 0.29885869 | N31: 1.1318886 | O31: -0.3797665 | P31: 0.43776298 | Q31: -0.51923509 | R31: -0.81328937
B32: h = TANH of that: | C32: =TANH(C31) -> 0.2841416 | D32: =TANH(D31) -> -0.032709662 | E32: =TANH(E31) -> -0.44548806 | F32: =TANH(F31) -> -0.86108994 | G32: =TANH(G31) -> 0.43810998 | H32: =TANH(H31) -> -0.73956847 | I32: =TANH(I31) -> -0.17210195 | J32: =TANH(J31) -> -0.42958612 | ... R32: =TANH(R31) -> -0.67140085
B33: TANH squashes every number into -1..1. This nonlinearity is what makes it a neural network and not just one big matrix.
B35: STEP 7 · SCORE EVERY WORD (MMULT #3, on the Prediction tab)
B36: The 16 numbers in h are multiplied against the 2627 x 16 Output Weights matrix in ONE formula:
B37: The formula MMULT(Output Weights, TRANSPOSE(h)) makes 2,628 scores at once; softmax turns them into probabilities.
B38: temperature | C38: 1 | D38: <- editable. Low (0.3) = confident and repetitive. High (3.0) = adventurous and random.
B40: STEP 8 · THE PREDICTION
B41: next word: | C41: =C45 -> head | E41: probability: | F41: =D45 -> 0.060397648
B44: rank | C44: word | D44: probability | E44: p as a bar
B45: 1 | C45: =INDEX(Prediction!$B$6:$B$2633,MATCH(LARGE(Prediction!$F$6:$F$2633,B45),Prediction!$F$6:$F$2633,0)) -> head | D45: =INDEX(Prediction!$E$6:$E$2633,MATCH(LARGE(Prediction!$F$6:$F$2633,B45),Prediction!$F$6:$F$2633,0)) -> 0.060397648 | E45: =REPT("|",MAX(1,ROUND(D45*60,0))) -> ||||
B46: 2 | C46: =INDEX(Prediction!$B$6:$B$2633,MATCH(LARGE(Prediction!$F$6:$F$2633,B46),Prediction!$F$6:$F$2633,0)) -> to | D46: =INDEX(Prediction!$E$6:$E$2633,MATCH(LARGE(Prediction!$F$6:$F$2633,B46),Prediction!$F$6:$F$2633,0)) -> 0.037169983 | E46: =REPT("|",MAX(1,ROUND(D46*60,0))) -> ||
B47: 3 | C47: =INDEX(Prediction!$B$6:$B$2633,MATCH(LARGE(Prediction!$F$6:$F$2633,B47),Prediction!$F$6:$F$2633,0)) -> and | D47: =INDEX(Prediction!$E$6:$E$2633,MATCH(LARGE(Prediction!$F$6:$F$2633,B47),Prediction!$F$6:$F$2633,0)) -> 0.03321316 | E47: =REPT("|",MAX(1,ROUND(D47*60,0))) -> ||
B48: 4 | C48: =INDEX(Prediction!$B$6:$B$2633,MATCH(LARGE(Prediction!$F$6:$F$2633,B48),Prediction!$F$6:$F$2633,0)) -> face | D48: =INDEX(Prediction!$E$6:$E$2633,MATCH(LARGE(Prediction!$F$6:$F$2633,B48),Prediction!$F$6:$F$2633,0)) -> 0.026646035 | E48: =REPT("|",MAX(1,ROUND(D48*60,0))) -> ||
B49: 5 | C49: =INDEX(Prediction!$B$6:$B$2633,MATCH(LARGE(Prediction!$F$6:$F$2633,B49),Prediction!$F$6:$F$2633,0)) -> sister | D49: =INDEX(Prediction!$E$6:$E$2633,MATCH(LARGE(Prediction!$F$6:$F$2633,B49),Prediction!$F$6:$F$2633,0)) -> 0.021229549 | E49: =REPT("|",MAX(1,ROUND(D49*60,0))) -> |
B50: 6 | C50: =INDEX(Prediction!$B$6:$B$2633,MATCH(LARGE(Prediction!$F$6:$F$2633,B50),Prediction!$F$6:$F$2633,0)) -> alice | D50: =INDEX(Prediction!$E$6:$E$2633,MATCH(LARGE(Prediction!$F$6:$F$2633,B50),Prediction!$F$6:$F$2633,0)) -> 0.020754178 | E50: =REPT("|",MAX(1,ROUND(D50*60,0))) -> |
...

Sheet How It Works
B1: HOW THIS TINY LLM WORKS
B3: THE BIG PICTURE
B4: A language model does one thing: given some words, it assigns a probability to every possible next word.
B5: That is the entire trick. Chatbots just do this over and over, feeding each predicted word back in.
B6: This workbook is that loop's single step, small enough that you can read every number involved.
B8: STEP A: TOKENIZE
B9: Your words are looked up in the Vocabulary tab, which holds every distinct word in Alice in Wonderland.
B10: Formula: =IFERROR(MATCH(word, Vocabulary!B:B, 0), 1). The row number IS the token ID.
B11: A word the book never uses gets ID 1, the <unk> token, whose embedding is all zeros so it contributes nothing.
B12: Real LLMs tokenize into subwords (pieces like "un", "believ", "able") so no word is ever unknown.
B14: STEP B: EMBED
B15: Token IDs are arbitrary row numbers; you cannot do math on them. So each ID looks up a row of 16 numbers
... B66: But the pipeline you can trace on the Prompt tab is, step for step, the real thing.

Sheet Tokenizer
B1: TOKENIZER: FROM TEXT TO NUMBERS
B2: Models cannot read letters. The first job is turning text into token IDs.
B4: When the book was prepared, all text was lowercased and split on anything that is not a letter or an
B5: apostrophe. So "Rabbit-hole!" became two tokens, "rabbit" and "hole". Every distinct word got one row
B6: in the Vocabulary tab, ordered by frequency, and that row number is its token ID forever.
B7: The Prompt tab cleans your typing the same way: lowercase, strip . , ! ? and spaces, then MATCH.
B9: LIVE DEMO: TYPE ANYTHING IN THE YELLOW CELL
B10: Curiouser! | C10: <- your raw text
B11: =LOWER(B10) -> curiouser! | C11: step 1: LOWER() lowercases it
B12: =SUBSTITUTE(SUBSTITUTE(SUBSTITUTE(SUBSTITUTE(B11,".",""),",",""),"!",""),"?","") -> curiouser | C12: step 2: SUBSTITUTE() strips . , ! ?
B13: =TRIM(B12) -> curiouser | C13: step 3: TRIM() removes stray spaces
B14: =IFERROR(MATCH(B13,Vocabulary!$B$2:$B$2629,0),1) -> 1135 | C14: step 4: MATCH() finds its row in the Vocabulary tab: the token ID (unknown words get 1, <unk>)
B15: =INDEX(Vocabulary!$B$2:$B$2629,B14) -> curiouser | C15: step 5: INDEX() reads back what token that ID belongs to
B16: =INDEX(Vocabulary!$C$2:$C$2629,B14) -> 2 | C16: bonus: how many times the book uses this word
B18: Real LLMs use subword tokenization (byte pair encoding). Rare words split into common pieces, so the
B19: model never meets a truly unknown word. With word-level tokens like ours, anything outside the book
B20: is a dead end: type "computer" on the Prompt tab and watch it become <unk> and get ignored.

Sheet Vocabulary
A1: Token ID | B1: Word | C1: Count | D1: Share | F1: Every distinct word in Alice in Wonderland, ordered by frequency. Row number = token ID. Token 1 is <unk>, the catch-all for words the book never uses.
A2: 1 | B2: <unk> | C2: 0 | D2: =C2/SUM($C$2:$C$2629) -> 0
A3: 2 | B3: the | C3: 1643 | D3: =C3/SUM($C$2:$C$2629) -> 0.061574785
A4: 3 | B4: and | C4: 872 | D4: =C4/SUM($C$2:$C$2629) -> 0.032679984
A5: 4 | B5: to | C5: 729 | D5: =C5/SUM($C$2:$C$2629) -> 0.027320766
A6: 5 | B6: a | C6: 632 | D6: =C6/SUM($C$2:$C$2629) -> 0.023685493
A7: 6 | B7: she | C7: 541 | D7: =C7/SUM($C$2:$C$2629) -> 0.020275082
A8: 7 | B8: it | C8: 530 | D8: =C8/SUM($C$2:$C$2629) -> 0.019862834
A9: 8 | B9: of | C9: 514 | D9: =C9/SUM($C$2:$C$2629) -> 0.019263201
A10: 9 | B10: said | C10: 462 | D10: =C10/SUM($C$2:$C$2629) -> 0.017314395
A11: 10 | B11: i | C11: 410 | D11: =C11/SUM($C$2:$C$2629) -> 0.015365589
A12: 11 | B12: alice | C12: 386 | D12: =C12/SUM($C$2:$C$2629) -> 0.014466139
A13: 12 | B13: in | C13: 368 | D13: =C13/SUM($C$2:$C$2629) -> 0.013791553
... A2629: 2628 | B2629: happy | C2629: 1 | D2629: =C2629/SUM($C$2:$C$2629) -> 3.7477045e-05

Sheet Embeddings
A1: Token ID | B1: Word | C1: d1 | D1: d2 | E1: d3 | F1: d4 | G1: d5 | H1: d6 | I1: d7 | J1: d8 | K1: d9 | L1: d10 | M1: d11 | N1: d12 | O1: d13 | P1: d14 | Q1: d15 | R1: d16 | T1: Learned INPUT embeddings: what each token means to the model. Learned by gradient descent, not designed. Row 2 is <unk>: all zeros on purpose so unknown words contribute nothing.
A2: 1 | B2: <unk> | C2: 0 | D2: 0 | E2: 0 | F2: 0 | G2: 0 | H2: 0 | I2: 0 | J2: 0 | K2: 0 | L2: 0 | M2: 0 | N2: 0 | O2: 0 | P2: 0 | Q2: 0 | R2: 0
A3: 2 | B3: the | C3: 0.0014 | D3: -0.01444 | E3: 0.68565 | F3: -0.2708 | G3: 0.4278 | H3: -1.10243 | I3: 0.52591 | J3: -0.90881 | K3: -0.59491 | L3: 0.11036 | M3: -0.14664 | N3: -0.05434 | O3: -0.04863 | P3: -0.16199 | Q3: 0.75159 | R3: -0.67193
A4: 3 | B4: and | C4: -0.46631 | D4: -0.52512 | E4: 0.23602 | F4: 0.13945 | G4: -0.46112 | H4: 0.23585 | I4: -0.76445 | J4: -0.20869 | K4: 0.73228 | L4: -0.01406 | M4: 0.15608 | N4: -0.17442 | O4: 0.47795 | P4: -0.34015 | Q4: -0.05513 | R4: 0.29304
A5: 4 | B5: to | C5: 0.16795 | D5: -0.3044 | E5: -0.09254 | F5: 0.44034 | G5: -0.96838 | H5: 0.09777 | I5: -0.48663 | J5: -1.04391 | K5: -0.01907 | L5: 1.00004 | M5: 0.10685 | N5: 0.97714 | O5: 0.11013 | P5: -1.52558 | Q5: -0.7094 | R5: -0.4149
A6: 5 | B6: a | C6: 0.13912 | D6: 0.56478 | E6: -0.27564 | F6: 1.20118 | G6: 0.48198 | H6: -1.51398 | I6: -0.57608 | J6: -0.96167 | K6: -0.42583 | L6: 0.29513 | M6: -0.19399 | N6: -0.15899 | O6: 0.91753 | P6: -0.14796 | Q6: 0.83875 | R6: -0.31755
A7: 6 | B7: she | C7: -0.50977 | D7: -0.44952 | E7: 0.12941 | F7: -0.71774 | G7: 0.05429 | H7: -0.23743 | I7: -0.80862 | J7: 0.68543 | K7: -0.48651 | L7: -0.87696 | M7: 0.99537 | N7: 0.3046 | O7: 0.26889 | P7: -0.77441 | Q7: -0.35463 | R7: -0.01709
A8: 7 | B8: it | C8: -0.44198 | D8: 0.07319 | E8: 0.51615 | F8: -0.30279 | G8: 0.36215 | H8: 0.24899 | I8: -0.41816 | J8: 0.34595 | K8: -0.13658 | L8: 0.25898 | M8: 0.31009 | N8: -0.16135 | O8: 0.41939 | P8: -0.31081 | Q8: 0.17521 | R8: -0.07899
A9: 8 | B9: of | C9: 0.22611 | D9: -1.48836 | E9: -0.49849 | F9: -0.26824 | G9: -0.66324 | H9: -0.79984 | I9: 0.91815 | J9: 0.22208 | K9: -0.03906 | L9: 0.41341 | M9: 0.52375 | N9: 0.30794 | O9: 0.12031 | P9: -0.14427 | Q9: 0.7189 | R9: -0.91312
A10: 9 | B10: said | C10: -0.08648 | D10: -0.62171 | E10: 0.50626 | F10: -0.55455 | G10: -0.51369 | H10: -0.46366 | I10: -0.66604 | J10: -0.69997 | K10: 0.73731 | L10: 0.23935 | M10: 0.18057 | N10: 0.89152 | O10: 0.47376 | P10: -0.11792 | Q10: -0.16247 | R10: -0.25391
A11: 10 | B11: i | C11: -1.469 | D11: 0.57971 | E11: -0.59044 | F11: -0.16685 | G11: 0.51828 | H11: 0.17004 | I11: -0.55053 | J11: -0.54416 | K11: -1.15394 | L11: 0.61319 | M11: 1.22721 | N11: 0.44036 | O11: -0.35888 | P11: -0.39221 | Q11: -1.10203 | R11: -0.02711
A12: 11 | B12: alice | C12: -0.70241 | D12: -0.39532 | E12: 0.37486 | F12: -0.18296 | G12: 0.27437 | H12: -0.36195 | I12: -0.64191 | J12: 0.33213 | K12: 0.21904 | L12: -0.21508 | M12: 0.2975 | N12: 0.81699 | O12: 0.25327 | P12: -0.00307 | Q12: -0.05965 | R12: 0.02406
A13: 12 | B13: in | C13: 0.30539 | D13: -0.609 | E13: 0.21038 | F13: 0.05819 | G13: -0.60489 | H13: -0.31163 | I13: 0.20301 | J13: 0.14679 | K13: 0.81843 | L13: 1.31922 | M13: -0.07081 | N13: 0.63405 | O13: -0.06821 | P13: -0.06042 | Q13: 0.92638 | R13: -0.37734
... A2629: 2628 | B2629: happy | C2629: 1.46493 | D2629: 2.14249 | E2629: -2.82616 | F2629: 2.47612 | G2629: -1.07191 | H2629: -0.81001 | I2629: -0.17219 | J2629: 0.1293 | K2629: -1.09594 | L2629: 1.03908 | M2629: -1.02163 | N2629: -0.41372 | O2629: -0.35856 | P2629: 0.32805 | Q2629: -0.386 | R2629: 0.66269

Sheet Output Weights
A1: Token ID | B1: Word | C1: d1 | D1: d2 | E1: d3 | F1: d4 | G1: d5 | H1: d6 | I1: d7 | J1: d8 | K1: d9 | L1: d10 | M1: d11 | N1: d12 | O1: d13 | P1: d14 | Q1: d15 | R1: d16 | T1: Learned OUTPUT projection: each word's "detector". Its score is the dot product of this row with the hidden vector h, computed for all rows at once by MMULT on the Prediction tab.
A2: 1 | B2: <unk> | C2: 0 | D2: 0 | E2: 0 | F2: 0 | G2: 0 | H2: 0 | I2: 0 | J2: 0 | K2: 0 | L2: 0 | M2: 0 | N2: 0 | O2: 0 | P2: 0 | Q2: 0 | R2: 0
A3: 2 | B3: the | C3: 2.27011 | D3: 1.27982 | E3: -1.91247 | F3: -3.11876 | G3: 0.19791 | H3: -0.50436 | I3: -0.58436 | J3: 1.28685 | K3: 2.25089 | L3: 1.20071 | M3: 2.23928 | N3: 1.72568 | O3: -2.15066 | P3: 1.20308 | Q3: 0.73017 | R3: 1.17279
A4: 3 | B4: and | C4: 2.56224 | D4: -1.38612 | E4: -2.56948 | F4: -2.13654 | G4: -1.00497 | H4: -2.54288 | I4: -1.42331 | J4: 1.11256 | K4: 1.55021 | L4: 0.34323 | M4: -1.23368 | N4: 2.51165 | O4: -0.15791 | P4: 1.61507 | Q4: 1.2631 | R4: -0.52672
A5: 4 | B5: to | C5: 1.25574 | D5: 1.11191 | E5: -3.10553 | F5: -2.93905 | G5: 0.08997 | H5: -2.73185 | I5: 0.95482 | J5: 1.22683 | K5: -0.32103 | L5: 0.96473 | M5: -0.64948 | N5: 1.7902 | O5: -0.65371 | P5: 0.95143 | Q5: 0.92967 | R5: 2.23965
A6: 5 | B6: a | C6: 0.65118 | D6: 1.01319 | E6: -2.21264 | F6: -2.05187 | G6: 0.01179 | H6: -0.42912 | I6: 1.1958 | J6: 2.31377 | K6: 1.52274 | L6: 0.78669 | M6: 1.42514 | N6: 0.34663 | O6: -1.93761 | P6: 2.06341 | Q6: -0.03386 | R6: 1.8396
A7: 6 | B7: she | C7: 3.43762 | D7: 1.02705 | E7: -3.13307 | F7: -1.7029 | G7: -1.30007 | H7: -1.47629 | I7: -0.44709 | J7: 1.14255 | K7: 0.81106 | L7: 0.18988 | M7: 0.58823 | N7: 0.86352 | O7: -0.40673 | P7: 0.74497 | Q7: 0.27928 | R7: -1.57692
A8: 7 | B8: it | C8: 2.61276 | D8: -0.31428 | E8: -1.34096 | F8: -2.2469 | G8: -0.61614 | H8: -1.39109 | I8: 0.04086 | J8: 2.26992 | K8: 2.01486 | L8: -0.20284 | M8: 1.4369 | N8: 1.76469 | O8: -1.73928 | P8: 1.38892 | Q8: -1.18588 | R8: -0.17847
A9: 8 | B9: of | C9: 1.44818 | D9: -0.878 | E9: -3.30061 | F9: -0.21264 | G9: 3.69233 | H9: -2.3373 | I9: -0.32576 | J9: 0.38634 | K9: 0.76297 | L9: 0.20838 | M9: -2.04111 | N9: 1.21817 | O9: -1.68751 | P9: -0.80226 | Q9: 1.80647 | R9: 1.00331
A10: 9 | B10: said | C10: 1.35778 | D10: 1.87971 | E10: -3.04444 | F10: -0.62001 | G10: -0.97905 | H10: 0.24719 | I10: -1.10514 | J10: 1.75231 | K10: 2.2981 | L10: -0.70622 | M10: -0.07377 | N10: 1.25768 | O10: -1.77699 | P10: 1.15333 | Q10: 1.21749 | R10: 0.24919
A11: 10 | B11: i | C11: 1.08425 | D11: 0.84231 | E11: -1.88262 | F11: -2.64202 | G11: -1.58129 | H11: -1.95331 | I11: -1.10056 | J11: 2.53445 | K11: 1.0482 | L11: 0.00272 | M11: -0.73627 | N11: 1.55166 | O11: -1.06221 | P11: 0.43194 | Q11: -0.48686 | R11: -0.82131
A12: 11 | B12: alice | C12: 3.30265 | D12: 0.68517 | E12: -1.8723 | F12: -1.06135 | G12: -2.46101 | H12: -1.62587 | I12: -0.1252 | J12: 0.11518 | K12: 0.35814 | L12: 1.47859 | M12: 1.03848 | N12: 2.46968 | O12: -1.24333 | P12: 0.55851 | Q12: 0.9965 | R12: 0.19473
A13: 12 | B13: in | C13: 0.31671 | D13: -1.50613 | E13: -2.8153 | F13: -2.32118 | G13: 0.82591 | H13: -1.69272 | I13: -1.01143 | J13: 0.32481 | K13: 1.61964 | L13: 1.41591 | M13: 0.50111 | N13: 0.99805 | O13: -0.41905 | P13: 1.70553 | Q13: 2.2822 | R13: 0.11632
... A2629: 2628 | B2629: happy | C2629: -0.49621 | D2629: -0.76182 | E2629: 1.78479 | F2629: 1.17916 | G2629: 0.53681 | H2629: 0.33683 | I2629: 0.46496 | J2629: -1.70535 | K2629: 0.25987 | L2629: 0.07508 | M2629: -0.68104 | N2629: -0.36244 | O2629: 0.99817 | P2629: -0.3626 | Q2629: -0.42018 | R2629: 0.11976

Sheet Hidden Weights
B1: HIDDEN LAYER WEIGHTS W (16 x 16)
C2: to d1 | D2: to d2 | E2: to d3 | F2: to d4 | G2: to d5 | H2: to d6 | I2: to d7 | J2: to d8 | K2: to d9 | L2: to d10 | M2: to d11 | N2: to d12 | O2: to d13 | P2: to d14 | Q2: to d15 | R2: to d16
B3: from d1 | C3: 0.11398 | D3: -0.61985 | E3: 0.91393 | F3: -0.28235 | G3: -0.36134 | H3: 0.33204 | I3: 0.63727 | J3: -0.49675 | K3: -0.01754 | L3: 0.11654 | M3: 0.01013 | N3: 0.26294 | O3: -0.26563 | P3: -0.4777 | Q3: -0.06753 | R3: 0.06078
B4: from d2 | C4: -0.53301 | D4: -0.32163 | E4: 0.24148 | F4: 0.47036 | G4: -0.76405 | H4: -0.186 | I4: -0.11269 | J4: 0.51772 | K4: 0.44239 | L4: -0.04808 | M4: 0.39816 | N4: -0.01211 | O4: 0.66346 | P4: -0.3604 | Q4: 0.06846 | R4: 0.25765
B5: from d3 | C5: -0.08972 | D5: -0.51373 | E5: 0.27297 | F5: -0.09656 | G5: 0.12011 | H5: -0.31573 | I5: -0.13996 | J5: -0.12484 | K5: 0.18117 | L5: 0.74125 | M5: -0.25742 | N5: -0.72001 | O5: -0.05532 | P5: 0.53643 | Q5: 0.30348 | R5: 0.52546
B6: from d4 | C6: -0.26621 | D6: -0.34454 | E6: 0.12986 | F6: -0.04935 | G6: -0.23255 | H6: 0.47608 | I6: 0.14419 | J6: 0.35969 | K6: -0.79391 | L6: -0.12992 | M6: 0.03827 | N6: -0.13233 | O6: 0.10172 | P6: 0.86073 | Q6: -0.61997 | R6: -0.27418
B7: from d5 | C7: 0.16707 | D7: -0.40129 | E7: -0.54736 | F7: 0.26861 | G7: -0.22492 | H7: -0.46625 | I7: 0.14265 | J7: 0.15858 | K7: 0.24384 | L7: 0.15886 | M7: -0.97759 | N7: 0.07742 | O7: 0.05217 | P7: -0.1819 | Q7: -0.43778 | R7: -0.39287
B8: from d6 | C8: -0.08682 | D8: -0.45314 | E8: -0.23975 | F8: -0.24063 | G8: 0.19988 | H8: 0.68516 | I8: -0.59648 | J8: 0.67982 | K8: -0.13326 | L8: -0.05018 | M8: -0.25612 | N8: 0.39734 | O8: -0.04462 | P8: -0.23336 | Q8: 0.43635 | R8: 0.15743
B9: from d7 | C9: -0.09504 | D9: -0.39158 | E9: -0.23019 | F9: 0.6567 | G9: 0.73688 | H9: -0.01503 | I9: 0.25305 | J9: -0.23448 | K9: 0.11388 | L9: -0.21404 | M9: 0.15649 | N9: 0.06692 | O9: -0.19638 | P9: -0.18044 | Q9: -0.69312 | R9: 0.58465
B10: from d8 | C10: -0.5976 | D10: 0.15856 | E10: 0.14123 | F10: -0.23038 | G10: 0.06556 | H10: 0.19331 | I10: 0.20122 | J10: 0.11005 | K10: 0.77035 | L10: -0.64458 | M10: -0.33893 | N10: -0.88285 | O10: -0.43042 | P10: -0.08275 | Q10: 0.0513 | R10: -0.13316
B11: from d9 | C11: -0.33616 | D11: -0.20098 | E11: -0.69478 | F11: -0.68723 | G11: -0.15183 | H11: -0.17961 | I11: -0.21088 | J11: -0.0353 | K11: -0.07312 | L11: 0.63792 | M11: 0.45994 | N11: -0.34505 | O11: -0.53983 | P11: -0.38763 | Q11: -0.35059 | R11: -0.34267
B12: from d10 | C12: -0.01456 | D12: 0.40256 | E12: 0.30299 | F12: -0.31126 | G12: 0.18909 | H12: -0.15538 | I12: 0.54552 | J12: 1.24529 | K12: 0.01251 | L12: 0.41021 | M12: -0.13866 | N12: 0.32296 | O12: -0.07118 | P12: -0.16625 | Q12: -0.36215 | R12: 0.29657
B13: from d11 | C13: 0.15445 | D13: -0.11733 | E13: -0.88066 | F13: -0.57306 | G13: -0.60454 | H13: 0.23392 | I13: 0.57411 | J13: -0.11023 | K13: 0.07117 | L13: -0.39914 | M13: -0.0816 | N13: -0.16432 | O13: 0.22593 | P13: -0.01894 | Q13: 0.33365 | R13: 0.7464
B14: from d12 | C14: -0.55554 | D14: -0.00974 | E14: -0.01042 | F14: -0.14218 | G14: -0.40443 | H14: -0.39451 | I14: -0.32905 | J14: -0.11456 | K14: 0.09512 | L14: -0.36024 | M14: -0.03861 | N14: 0.84225 | O14: -0.73421 | P14: 0.46005 | Q14: -0.08381 | R14: 0.37969
... B18: from d16 | C18: -0.35621 | D18: 0.13093 | E18: -0.18331 | F18: 0.69139 | G18: -0.21284 | H18: 0.06356 | I18: 0.44676 | J18: 0.23418 | K18: -0.68827 | L18: 0.29684 | M18: -0.09855 | N18: -0.0743 | O18: -0.60637 | P18: -0.07631 | Q18: 0.62796 | R18: -0.15737
B21: Used on the Prompt tab as MMULT(context, W), then TANH. Each output dimension mixes all 16 input
B22: dimensions through these 256 learned numbers. There is no story behind any individual number;
B23: the matrix works as a whole. That opacity is real: interpretability is an open research problem.

Sheet Prediction
A1: SCORING ALL 2628 WORDS AT ONCE
A2: Column C is a single MMULT array formula: Output Weights (2628 x 16) times TRANSPOSE(h) (16 x 1) = 2628 logits.
A3: max logit | B3: =MAX(C6:C2633) -> 6.8294623 | C3: sum of exp | D3: =SUM(D6:D2633) -> 16.556936 | E3: temperature | F3: =Prompt!$C$38 -> 1
A5: Token ID | B5: Word | C5: Logit (MMULT) | D5: EXP((L-max)/T) | E5: Probability | F5: Rank helper | H5: Rank helper = probability + tokenID x 1E-10 (breaks ties), with <unk> forced to -1 so it can never be predicted. The Prompt tab ranks this column with LARGE + MATCH.
A6: 1 | B6: =Vocabulary!B2 -> <unk> | C6: {=MMULT('Output Weights'!$C$2:$R$2629,TRANSPOSE(Prompt!$C$32:$R$32))} -> 0 | D6: =EXP((C6-$B$3)/$F$3) -> 0.0010814394 | E6: =D6/$D$3 -> 6.5316399e-05 | F6: =IF(A6=1,-1,E6+A6*0.0000000001) -> -1
A7: 2 | B7: =Vocabulary!B3 -> the | C7: 5.4637011 | D7: =EXP((C7-$B$3)/$F$3) -> 0.25518635 | E7: =D7/$D$3 -> 0.015412656 | F7: =IF(A7=1,-1,E7+A7*0.0000000001) -> 0.015412656
A8: 3 | B8: =Vocabulary!B4 -> and | C8: 6.2314583 | D8: =EXP((C8-$B$3)/$F$3) -> 0.54990816 | E8: =D8/$D$3 -> 0.03321316 | F8: =IF(A8=1,-1,E8+A8*0.0000000001) -> 0.03321316
A9: 4 | B9: =Vocabulary!B5 -> to | C9: 6.3440137 | D9: =EXP((C9-$B$3)/$F$3) -> 0.61542104 | E9: =D9/$D$3 -> 0.037169983 | F9: =IF(A9=1,-1,E9+A9*0.0000000001) -> 0.037169984
A10: 5 | B10: =Vocabulary!B6 -> a | C10: 2.4487274 | D10: =EXP((C10-$B$3)/$F$3) -> 0.012516158 | E10: =D10/$D$3 -> 0.00075594648 | F10: =IF(A10=1,-1,E10+A10*0.0000000001) -> 0.00075594698
A11: 6 | B11: =Vocabulary!B7 -> she | C11: 5.7067032 | D11: =EXP((C11-$B$3)/$F$3) -> 0.32538078 | E11: =D11/$D$3 -> 0.019652234 | F11: =IF(A11=1,-1,E11+A11*0.0000000001) -> 0.019652235
A12: 7 | B12: =Vocabulary!B8 -> it | C12: 5.2626394 | D12: =EXP((C12-$B$3)/$F$3) -> 0.20870722 | E12: =D12/$D$3 -> 0.012605425 | F12: =IF(A12=1,-1,E12+A12*0.0000000001) -> 0.012605426
A13: 8 | B13: =Vocabulary!B9 -> of | C13: 4.058619 | D13: =EXP((C13-$B$3)/$F$3) -> 0.062609186 | E13: =D13/$D$3 -> 0.0037814476 | F13: =IF(A13=1,-1,E13+A13*0.0000000001) -> 0.0037814484
A14: 9 | B14: =Vocabulary!B10 -> said | C14: 0.37796069 | D14: =EXP((C14-$B$3)/$F$3) -> 0.0015781506 | E14: =D14/$D$3 -> 9.5316585e-05 | F14: =IF(A14=1,-1,E14+A14*0.0000000001) -> 9.5317485e-05
A15: 10 | B15: =Vocabulary!B11 -> i | C15: 4.9036235 | D15: =EXP((C15-$B$3)/$F$3) -> 0.14575344 | E15: =D15/$D$3 -> 0.0088031653 | F15: =IF(A15=1,-1,E15+A15*0.0000000001) -> 0.0088031663
A16: 11 | B16: =Vocabulary!B12 -> alice | C16: 5.7612597 | D16: =EXP((C16-$B$3)/$F$3) -> 0.34362559 | E16: =D16/$D$3 -> 0.020754178 | F16: =IF(A16=1,-1,E16+A16*0.0000000001) -> 0.020754179
A17: 12 | B17: =Vocabulary!B13 -> in | C17: 5.3796782 | D17: =EXP((C17-$B$3)/$F$3) -> 0.23462094 | E17: =D17/$D$3 -> 0.014170553 | F17: =IF(A17=1,-1,E17+A17*0.0000000001) -> 0.014170554
A18: 13 | B18: =Vocabulary!B14 -> you | C18: 1.6168542 | D18: =EXP((C18-$B$3)/$F$3) -> 0.0054474479 | E18: =D18/$D$3 -> 0.00032901304 | F18: =IF(A18=1,-1,E18+A18*0.0000000001) -> 0.00032901434
... A2633: 2628 | B2633: =Vocabulary!B2629 -> happy | C2633: -2.3092825 | D2633: =EXP((C2633-$B$3)/$F$3) -> 0.00010742208 | E2633: =D2633/$D$3 -> 6.4880412e-06 | F2633: =IF(A2633=1,-1,E2633+A2633*0.0000000001) -> 6.7508412e-06
