Workbook

Sheet README
B1: A TINY LLM IN A SPREADSHEET, WITH ITS TRAINING OPENED UP
B2: A working next-word predictor trained on Alice in Wonderland: 10-word context, learned attention, live backpropagation.
B4: WHAT THIS IS
B5: A real (very small) neural language model. It reads the last 10 words, blends them with attention weights it
B6: learned by itself, passes them through a hidden layer, and scores all 2627 words of the book's vocabulary.
B7: It was trained by gradient descent on 26,673 ten-word windows from the book, and this workbook does not just
B8: run the model: the Training Example and Backpropagation tabs recompute a real training step, live.
B10: START HERE
B11: Prompt tab: type up to 10 words in the yellow cells, watch every step, read the prediction.
B12: Training Example tab: one real passage from the book, the forward pass, and the loss.
B13: Backpropagation tab: the actual gradients for that example, computed with MMULT, ending in a weight update.
B14: Circuits & Activations tab: a live trace of WHY the model picked its word, neuron by neuron.
... B40: so you never have to distribute words across cells by hand.

Sheet Prompt
B1: A TINY LLM: TYPE WORDS, WATCH IT THINK
B2: Yellow cells are inputs. Ten-word context; the model learned its own attention weights. Read top to bottom.
B4: STEP 1 · YOUR PROMPT (up to 10 words; blanks become <unk> and are ignored)
B5: w1 (oldest) | C5: w2 | D5: w3 | E5: w4 | F5: w5 | G5: w6 | H5: w7 | I5: w8 | J5: w9 | K5: w10 (latest)
B6: and | C6: whether | D6: the | E6: pleasure | F6: of | G6: making | H6: a | I6: daisy | J6: chain | K6: would
B7: or paste a sentence: | M7: =IF($C$7="",0,LEN(TRIM($C$7))-LEN(SUBSTITUTE(TRIM($C$7)," ",""))+1) -> 0
B8: If the sentence cell is filled, its LAST 10 words are used and the word cells above are ignored; clear it to use the cells. Default prompt: the book's second sentence, cut off; the true next word is "be".
B9: STEP 2 · TOKENIZE (find each word's row in the Vocabulary tab)
B10: =IF($C$7="",TRIM(SUBSTITUTE(SUBSTITUTE(SUBSTITUTE(SUBSTITUTE(LOWER(B6),".",""),",",""),"!",""),"?","")),IF($M$7-10+1<1,"",TRIM(SUBSTITUTE(SUBSTITUTE(SUBSTITUTE(SUBSTITUTE(LOWER(TRIM(MID(SUBSTITUTE(TRIM($C$7)," ",REPT(" ",LEN($C$7))),($M$7-10+1-1)*LEN($C$7)+1,LEN($C$7)))),".",""),",",""),"!",""),"?","")))) -> and | C10: =IF($C$7="",TRIM(SUBSTITUTE(SUBSTITUTE(SUBSTITUTE(SUBSTITUTE(LOWER(C6),".",""),",",""),"!",""),"?","")),IF($M$7-10+2<1,"",TRIM(SUBSTITUTE(SUBSTITUTE(SUBSTITUTE(SUBSTITUTE(LOWER(TRIM(MID(SUBSTITUTE(TRIM($C$7)," ",REPT(" ",LEN($C$7))),($M$7-10+2-1)*LEN($C$7)+1,LEN($C$7)))),".",""),",",""),"!",""),"?","")))) -> whether | D10: =IF($C$7="",TRIM(SUBSTITUTE(SUBSTITUTE(SUBSTITUTE(SUBSTITUTE(LOWER(D6),".",""),",",""),"!",""),"?","")),IF($M$7-10+3<1,"",TRIM(SUBSTITUTE(SUBSTITUTE(SUBSTITUTE(SUBSTITUTE(LOWER(TRIM(MID(SUBSTITUTE(TRIM($C$7)," ",REPT(" ",LEN($C$7))),($M$7-10+3-1)*LEN($C$7)+1,LEN($C$7)))),".",""),",",""),"!",""),"?","")))) -> the | E10: =IF($C$7="",TRIM(SUBSTITUTE(SUBSTITUTE(SUBSTITUTE(SUBSTITUTE(LOWER(E6),".",""),",",""),"!",""),"?","")),IF($M$7-10+4<1,"",TRIM(SUBSTITUTE(SUBSTITUTE(SUBSTITUTE(SUBSTITUTE(LOWER(TRIM(MID(SUBSTITUTE(TRIM($C$7)," ",REPT(" ",LEN($C$7))),($M$7-10+4-1)*LEN($C$7)+1,LEN($C$7)))),".",""),",",""),"!",""),"?","")))) -> pleasure | F10: =IF($C$7="",TRIM(SUBSTITUTE(SUBSTITUTE(SUBSTITUTE(SUBSTITUTE(LOWER(F6),".",""),",",""),"!",""),"?","")),IF($M$7-10+5<1,"",TRIM(SUBSTITUTE(SUBSTITUTE(SUBSTITUTE(SUBSTITUTE(LOWER(TRIM(MID(SUBSTITUTE(TRIM($C$7)," ",REPT(" ",LEN($C$7))),($M$7-10+5-1)*LEN($C$7)+1,LEN($C$7)))),".",""),",",""),"!",""),"?","")))) -> of | G10: =IF($C$7="",TRIM(SUBSTITUTE(SUBSTITUTE(SUBSTITUTE(SUBSTITUTE(LOWER(G6),".",""),",",""),"!",""),"?","")),IF($M$7-10+6<1,"",TRIM(SUBSTITUTE(SUBSTITUTE(SUBSTITUTE(SUBSTITUTE(LOWER(TRIM(MID(SUBSTITUTE(TRIM($C$7)," ",REPT(" ",LEN($C$7))),($M$7-10+6-1)*LEN($C$7)+1,LEN($C$7)))),".",""),",",""),"!",""),"?","")))) -> making | H10: =IF($C$7="",TRIM(SUBSTITUTE(SUBSTITUTE(SUBSTITUTE(SUBSTITUTE(LOWER(H6),".",""),",",""),"!",""),"?","")),IF($M$7-10+7<1,"",TRIM(SUBSTITUTE(SUBSTITUTE(SUBSTITUTE(SUBSTITUTE(LOWER(TRIM(MID(SUBSTITUTE(TRIM($C$7)," ",REPT(" ",LEN($C$7))),($M$7-10+7-1)*LEN($C$7)+1,LEN($C$7)))),".",""),",",""),"!",""),"?","")))) -> a | I10: =IF($C$7="",TRIM(SUBSTITUTE(SUBSTITUTE(SUBSTITUTE(SUBSTITUTE(LOWER(I6),".",""),",",""),"!",""),"?","")),IF($M$7-10+8<1,"",TRIM(SUBSTITUTE(SUBSTITUTE(SUBSTITUTE(SUBSTITUTE(LOWER(TRIM(MID(SUBSTITUTE(TRIM($C$7)," ",REPT(" ",LEN($C$7))),($M$7-10+8-1)*LEN($C$7)+1,LEN($C$7)))),".",""),",",""),"!",""),"?","")))) -> daisy | J10: =IF($C$7="",TRIM(SUBSTITUTE(SUBSTITUTE(SUBSTITUTE(SUBSTITUTE(LOWER(J6),".",""),",",""),"!",""),"?","")),IF($M$7-10+9<1,"",TRIM(SUBSTITUTE(SUBSTITUTE(SUBSTITUTE(SUBSTITUTE(LOWER(TRIM(MID(SUBSTITUTE(TRIM($C$7)," ",REPT(" ",LEN($C$7))),($M$7-10+9-1)*LEN($C$7)+1,LEN($C$7)))),".",""),",",""),"!",""),"?","")))) -> chain | K10: =IF($C$7="",TRIM(SUBSTITUTE(SUBSTITUTE(SUBSTITUTE(SUBSTITUTE(LOWER(K6),".",""),",",""),"!",""),"?","")),IF($M$7-10+10<1,"",TRIM(SUBSTITUTE(SUBSTITUTE(SUBSTITUTE(SUBSTITUTE(LOWER(TRIM(MID(SUBSTITUTE(TRIM($C$7)," ",REPT(" ",LEN($C$7))),($M$7-10+10-1)*LEN($C$7)+1,LEN($C$7)))),".",""),",",""),"!",""),"?","")))) -> would
B11: =IFERROR(MATCH(B10,Vocabulary!$B$2:$B$2629,0),1) -> 3 | C11: =IFERROR(MATCH(C10,Vocabulary!$B$2:$B$2629,0),1) -> 328 | D11: =IFERROR(MATCH(D10,Vocabulary!$B$2:$B$2629,0),1) -> 2 | E11: =IFERROR(MATCH(E10,Vocabulary!$B$2:$B$2629,0),1) -> 1081 | F11: =IFERROR(MATCH(F10,Vocabulary!$B$2:$B$2629,0),1) -> 8 | G11: =IFERROR(MATCH(G10,Vocabulary!$B$2:$B$2629,0),1) -> 425 | H11: =IFERROR(MATCH(H10,Vocabulary!$B$2:$B$2629,0),1) -> 5 | I11: =IFERROR(MATCH(I10,Vocabulary!$B$2:$B$2629,0),1) -> 1490 | ... K11: =IFERROR(MATCH(K10,Vocabulary!$B$2:$B$2629,0),1) -> 48
B12: =IF(ISNUMBER(MATCH(B10,Vocabulary!$B$2:$B$2629,0)),"ok","<unk>") -> ok | C12: =IF(ISNUMBER(MATCH(C10,Vocabulary!$B$2:$B$2629,0)),"ok","<unk>") -> ok | D12: =IF(ISNUMBER(MATCH(D10,Vocabulary!$B$2:$B$2629,0)),"ok","<unk>") -> ok | E12: =IF(ISNUMBER(MATCH(E10,Vocabulary!$B$2:$B$2629,0)),"ok","<unk>") -> ok | F12: =IF(ISNUMBER(MATCH(F10,Vocabulary!$B$2:$B$2629,0)),"ok","<unk>") -> ok | G12: =IF(ISNUMBER(MATCH(G10,Vocabulary!$B$2:$B$2629,0)),"ok","<unk>") -> ok | H12: =IF(ISNUMBER(MATCH(H10,Vocabulary!$B$2:$B$2629,0)),"ok","<unk>") -> ok | I12: =IF(ISNUMBER(MATCH(I10,Vocabulary!$B$2:$B$2629,0)),"ok","<unk>") -> ok | ... K12: =IF(ISNUMBER(MATCH(K10,Vocabulary!$B$2:$B$2629,0)),"ok","<unk>") -> ok
B13: Row 10: cleaned (lowercase, strip . , ! ?). Row 11: token ID via MATCH. Full story on the Tokenizer tab.
B15: STEP 3 · EMBEDDINGS (each token ID looks up its learned row of 16 numbers: a 10 x 16 block)
B16: token | C16: d1 | D16: d2 | E16: d3 | F16: d4 | G16: d5 | H16: d6 | I16: d7 | J16: d8 | K16: d9 | L16: d10 | M16: d11 | N16: d12 | O16: d13 | P16: d14 | Q16: d15 | R16: d16
B17: =B10 -> and | C17: =INDEX(Embeddings!$C$2:$R$2629,B$11,COLUMN()-2) -> -0.25765 | D17: =INDEX(Embeddings!$C$2:$R$2629,B$11,COLUMN()-2) -> -0.27206 | E17: =INDEX(Embeddings!$C$2:$R$2629,B$11,COLUMN()-2) -> 1.0304 | F17: =INDEX(Embeddings!$C$2:$R$2629,B$11,COLUMN()-2) -> -0.35624 | G17: =INDEX(Embeddings!$C$2:$R$2629,B$11,COLUMN()-2) -> 0.0815 | H17: =INDEX(Embeddings!$C$2:$R$2629,B$11,COLUMN()-2) -> 0.64867 | I17: =INDEX(Embeddings!$C$2:$R$2629,B$11,COLUMN()-2) -> 0.45802 | J17: =INDEX(Embeddings!$C$2:$R$2629,B$11,COLUMN()-2) -> -0.48542 | K17: =INDEX(Embeddings!$C$2:$R$2629,B$11,COLUMN()-2) -> -0.40933 | L17: =INDEX(Embeddings!$C$2:$R$2629,B$11,COLUMN()-2) -> 0.10557 | M17: =INDEX(Embeddings!$C$2:$R$2629,B$11,COLUMN()-2) -> -0.48216 | N17: =INDEX(Embeddings!$C$2:$R$2629,B$11,COLUMN()-2) -> -0.51501 | O17: =INDEX(Embeddings!$C$2:$R$2629,B$11,COLUMN()-2) -> 0.07698 | P17: =INDEX(Embeddings!$C$2:$R$2629,B$11,COLUMN()-2) -> -0.14712 | Q17: =INDEX(Embeddings!$C$2:$R$2629,B$11,COLUMN()-2) -> 0.73348 | R17: =INDEX(Embeddings!$C$2:$R$2629,B$11,COLUMN()-2) -> -0.33239
B18: =C10 -> whether | C18: =INDEX(Embeddings!$C$2:$R$2629,C$11,COLUMN()-2) -> -1.86254 | D18: =INDEX(Embeddings!$C$2:$R$2629,C$11,COLUMN()-2) -> 0.23212 | E18: =INDEX(Embeddings!$C$2:$R$2629,C$11,COLUMN()-2) -> -1.32472 | F18: =INDEX(Embeddings!$C$2:$R$2629,C$11,COLUMN()-2) -> -1.14225 | G18: =INDEX(Embeddings!$C$2:$R$2629,C$11,COLUMN()-2) -> -0.22653 | H18: =INDEX(Embeddings!$C$2:$R$2629,C$11,COLUMN()-2) -> 0.53177 | I18: =INDEX(Embeddings!$C$2:$R$2629,C$11,COLUMN()-2) -> -0.55961 | J18: =INDEX(Embeddings!$C$2:$R$2629,C$11,COLUMN()-2) -> 0.06918 | K18: =INDEX(Embeddings!$C$2:$R$2629,C$11,COLUMN()-2) -> -0.95933 | L18: =INDEX(Embeddings!$C$2:$R$2629,C$11,COLUMN()-2) -> -2.22461 | M18: =INDEX(Embeddings!$C$2:$R$2629,C$11,COLUMN()-2) -> 1.23668 | N18: =INDEX(Embeddings!$C$2:$R$2629,C$11,COLUMN()-2) -> 2.11572 | O18: =INDEX(Embeddings!$C$2:$R$2629,C$11,COLUMN()-2) -> 0.28465 | P18: =INDEX(Embeddings!$C$2:$R$2629,C$11,COLUMN()-2) -> 0.11699 | Q18: =INDEX(Embeddings!$C$2:$R$2629,C$11,COLUMN()-2) -> 0.29215 | R18: =INDEX(Embeddings!$C$2:$R$2629,C$11,COLUMN()-2) -> -1.01482
B19: =D10 -> the | C19: =INDEX(Embeddings!$C$2:$R$2629,D$11,COLUMN()-2) -> -0.24612 | D19: =INDEX(Embeddings!$C$2:$R$2629,D$11,COLUMN()-2) -> -0.69257 | E19: =INDEX(Embeddings!$C$2:$R$2629,D$11,COLUMN()-2) -> -1.11074 | F19: =INDEX(Embeddings!$C$2:$R$2629,D$11,COLUMN()-2) -> -0.52835 | G19: =INDEX(Embeddings!$C$2:$R$2629,D$11,COLUMN()-2) -> -0.49587 | H19: =INDEX(Embeddings!$C$2:$R$2629,D$11,COLUMN()-2) -> 0.16979 | I19: =INDEX(Embeddings!$C$2:$R$2629,D$11,COLUMN()-2) -> -1.56429 | J19: =INDEX(Embeddings!$C$2:$R$2629,D$11,COLUMN()-2) -> -0.73668 | K19: =INDEX(Embeddings!$C$2:$R$2629,D$11,COLUMN()-2) -> 0.62002 | L19: =INDEX(Embeddings!$C$2:$R$2629,D$11,COLUMN()-2) -> 0.80283 | M19: =INDEX(Embeddings!$C$2:$R$2629,D$11,COLUMN()-2) -> -0.61923 | N19: =INDEX(Embeddings!$C$2:$R$2629,D$11,COLUMN()-2) -> -0.87934 | O19: =INDEX(Embeddings!$C$2:$R$2629,D$11,COLUMN()-2) -> -0.30187 | P19: =INDEX(Embeddings!$C$2:$R$2629,D$11,COLUMN()-2) -> 0.67991 | Q19: =INDEX(Embeddings!$C$2:$R$2629,D$11,COLUMN()-2) -> -0.28704 | R19: =INDEX(Embeddings!$C$2:$R$2629,D$11,COLUMN()-2) -> 0.23597
B20: =E10 -> pleasure | C20: =INDEX(Embeddings!$C$2:$R$2629,E$11,COLUMN()-2) -> -0.27592 | D20: =INDEX(Embeddings!$C$2:$R$2629,E$11,COLUMN()-2) -> -0.46226 | E20: =INDEX(Embeddings!$C$2:$R$2629,E$11,COLUMN()-2) -> -1.79933 | F20: =INDEX(Embeddings!$C$2:$R$2629,E$11,COLUMN()-2) -> -1.45504 | G20: =INDEX(Embeddings!$C$2:$R$2629,E$11,COLUMN()-2) -> 0.34007 | H20: =INDEX(Embeddings!$C$2:$R$2629,E$11,COLUMN()-2) -> -1.05535 | I20: =INDEX(Embeddings!$C$2:$R$2629,E$11,COLUMN()-2) -> 1.10641 | J20: =INDEX(Embeddings!$C$2:$R$2629,E$11,COLUMN()-2) -> 2.07358 | K20: =INDEX(Embeddings!$C$2:$R$2629,E$11,COLUMN()-2) -> 1.63027 | L20: =INDEX(Embeddings!$C$2:$R$2629,E$11,COLUMN()-2) -> 1.75805 | M20: =INDEX(Embeddings!$C$2:$R$2629,E$11,COLUMN()-2) -> -1.96145 | N20: =INDEX(Embeddings!$C$2:$R$2629,E$11,COLUMN()-2) -> -1.09477 | O20: =INDEX(Embeddings!$C$2:$R$2629,E$11,COLUMN()-2) -> -0.12867 | P20: =INDEX(Embeddings!$C$2:$R$2629,E$11,COLUMN()-2) -> 1.84758 | Q20: =INDEX(Embeddings!$C$2:$R$2629,E$11,COLUMN()-2) -> 0.02697 | R20: =INDEX(Embeddings!$C$2:$R$2629,E$11,COLUMN()-2) -> -3.24116
B21: =F10 -> of | C21: =INDEX(Embeddings!$C$2:$R$2629,F$11,COLUMN()-2) -> -0.05844 | D21: =INDEX(Embeddings!$C$2:$R$2629,F$11,COLUMN()-2) -> -0.69847 | E21: =INDEX(Embeddings!$C$2:$R$2629,F$11,COLUMN()-2) -> -0.01318 | F21: =INDEX(Embeddings!$C$2:$R$2629,F$11,COLUMN()-2) -> 0.69573 | G21: =INDEX(Embeddings!$C$2:$R$2629,F$11,COLUMN()-2) -> 0.40065 | H21: =INDEX(Embeddings!$C$2:$R$2629,F$11,COLUMN()-2) -> -0.26492 | I21: =INDEX(Embeddings!$C$2:$R$2629,F$11,COLUMN()-2) -> 1.42647 | J21: =INDEX(Embeddings!$C$2:$R$2629,F$11,COLUMN()-2) -> -0.65642 | K21: =INDEX(Embeddings!$C$2:$R$2629,F$11,COLUMN()-2) -> -0.65223 | L21: =INDEX(Embeddings!$C$2:$R$2629,F$11,COLUMN()-2) -> -0.7729 | M21: =INDEX(Embeddings!$C$2:$R$2629,F$11,COLUMN()-2) -> -0.26861 | N21: =INDEX(Embeddings!$C$2:$R$2629,F$11,COLUMN()-2) -> -0.03118 | O21: =INDEX(Embeddings!$C$2:$R$2629,F$11,COLUMN()-2) -> 0.01131 | P21: =INDEX(Embeddings!$C$2:$R$2629,F$11,COLUMN()-2) -> 0.69797 | Q21: =INDEX(Embeddings!$C$2:$R$2629,F$11,COLUMN()-2) -> -0.25873 | R21: =INDEX(Embeddings!$C$2:$R$2629,F$11,COLUMN()-2) -> 0.80276
B22: =G10 -> making | C22: =INDEX(Embeddings!$C$2:$R$2629,G$11,COLUMN()-2) -> 0.85812 | D22: =INDEX(Embeddings!$C$2:$R$2629,G$11,COLUMN()-2) -> 0.66564 | E22: =INDEX(Embeddings!$C$2:$R$2629,G$11,COLUMN()-2) -> 2.47402 | F22: =INDEX(Embeddings!$C$2:$R$2629,G$11,COLUMN()-2) -> 0.86201 | G22: =INDEX(Embeddings!$C$2:$R$2629,G$11,COLUMN()-2) -> -0.22479 | H22: =INDEX(Embeddings!$C$2:$R$2629,G$11,COLUMN()-2) -> 0.12082 | I22: =INDEX(Embeddings!$C$2:$R$2629,G$11,COLUMN()-2) -> 2.06183 | J22: =INDEX(Embeddings!$C$2:$R$2629,G$11,COLUMN()-2) -> 0.30828 | K22: =INDEX(Embeddings!$C$2:$R$2629,G$11,COLUMN()-2) -> 1.30011 | L22: =INDEX(Embeddings!$C$2:$R$2629,G$11,COLUMN()-2) -> -0.72049 | M22: =INDEX(Embeddings!$C$2:$R$2629,G$11,COLUMN()-2) -> 0.16129 | N22: =INDEX(Embeddings!$C$2:$R$2629,G$11,COLUMN()-2) -> 0.33156 | O22: =INDEX(Embeddings!$C$2:$R$2629,G$11,COLUMN()-2) -> -0.0888 | P22: =INDEX(Embeddings!$C$2:$R$2629,G$11,COLUMN()-2) -> 1.73543 | Q22: =INDEX(Embeddings!$C$2:$R$2629,G$11,COLUMN()-2) -> -0.67013 | R22: =INDEX(Embeddings!$C$2:$R$2629,G$11,COLUMN()-2) -> 0.25614
B23: =H10 -> a | C23: =INDEX(Embeddings!$C$2:$R$2629,H$11,COLUMN()-2) -> 0.44645 | D23: =INDEX(Embeddings!$C$2:$R$2629,H$11,COLUMN()-2) -> 0.35822 | E23: =INDEX(Embeddings!$C$2:$R$2629,H$11,COLUMN()-2) -> -0.33882 | F23: =INDEX(Embeddings!$C$2:$R$2629,H$11,COLUMN()-2) -> 0.46646 | G23: =INDEX(Embeddings!$C$2:$R$2629,H$11,COLUMN()-2) -> -0.49398 | H23: =INDEX(Embeddings!$C$2:$R$2629,H$11,COLUMN()-2) -> -0.35397 | I23: =INDEX(Embeddings!$C$2:$R$2629,H$11,COLUMN()-2) -> -1.67177 | J23: =INDEX(Embeddings!$C$2:$R$2629,H$11,COLUMN()-2) -> -1.32692 | K23: =INDEX(Embeddings!$C$2:$R$2629,H$11,COLUMN()-2) -> -0.02545 | L23: =INDEX(Embeddings!$C$2:$R$2629,H$11,COLUMN()-2) -> 0.24869 | M23: =INDEX(Embeddings!$C$2:$R$2629,H$11,COLUMN()-2) -> 0.63082 | N23: =INDEX(Embeddings!$C$2:$R$2629,H$11,COLUMN()-2) -> -0.58007 | O23: =INDEX(Embeddings!$C$2:$R$2629,H$11,COLUMN()-2) -> -0.04389 | P23: =INDEX(Embeddings!$C$2:$R$2629,H$11,COLUMN()-2) -> 0.52169 | Q23: =INDEX(Embeddings!$C$2:$R$2629,H$11,COLUMN()-2) -> -0.25329 | R23: =INDEX(Embeddings!$C$2:$R$2629,H$11,COLUMN()-2) -> 1.71116
B24: =I10 -> daisy | C24: =INDEX(Embeddings!$C$2:$R$2629,I$11,COLUMN()-2) -> -1.76346 | D24: =INDEX(Embeddings!$C$2:$R$2629,I$11,COLUMN()-2) -> 1.60316 | E24: =INDEX(Embeddings!$C$2:$R$2629,I$11,COLUMN()-2) -> 0.59665 | F24: =INDEX(Embeddings!$C$2:$R$2629,I$11,COLUMN()-2) -> -1.48118 | G24: =INDEX(Embeddings!$C$2:$R$2629,I$11,COLUMN()-2) -> -2.45447 | H24: =INDEX(Embeddings!$C$2:$R$2629,I$11,COLUMN()-2) -> 0.63032 | I24: =INDEX(Embeddings!$C$2:$R$2629,I$11,COLUMN()-2) -> -1.51319 | J24: =INDEX(Embeddings!$C$2:$R$2629,I$11,COLUMN()-2) -> -4.36859 | K24: =INDEX(Embeddings!$C$2:$R$2629,I$11,COLUMN()-2) -> 1.34154 | L24: =INDEX(Embeddings!$C$2:$R$2629,I$11,COLUMN()-2) -> 0.5695 | M24: =INDEX(Embeddings!$C$2:$R$2629,I$11,COLUMN()-2) -> 1.10327 | N24: =INDEX(Embeddings!$C$2:$R$2629,I$11,COLUMN()-2) -> 0.36804 | O24: =INDEX(Embeddings!$C$2:$R$2629,I$11,COLUMN()-2) -> -0.98829 | P24: =INDEX(Embeddings!$C$2:$R$2629,I$11,COLUMN()-2) -> -2.72809 | Q24: =INDEX(Embeddings!$C$2:$R$2629,I$11,COLUMN()-2) -> 1.36047 | R24: =INDEX(Embeddings!$C$2:$R$2629,I$11,COLUMN()-2) -> -2.40981
B25: =J10 -> chain | C25: =INDEX(Embeddings!$C$2:$R$2629,J$11,COLUMN()-2) -> 0.8676 | D25: =INDEX(Embeddings!$C$2:$R$2629,J$11,COLUMN()-2) -> -2.48009 | E25: =INDEX(Embeddings!$C$2:$R$2629,J$11,COLUMN()-2) -> 2.44397 | F25: =INDEX(Embeddings!$C$2:$R$2629,J$11,COLUMN()-2) -> -0.95178 | G25: =INDEX(Embeddings!$C$2:$R$2629,J$11,COLUMN()-2) -> -0.14695 | H25: =INDEX(Embeddings!$C$2:$R$2629,J$11,COLUMN()-2) -> -0.59088 | I25: =INDEX(Embeddings!$C$2:$R$2629,J$11,COLUMN()-2) -> -1.10541 | J25: =INDEX(Embeddings!$C$2:$R$2629,J$11,COLUMN()-2) -> 3.07254 | K25: =INDEX(Embeddings!$C$2:$R$2629,J$11,COLUMN()-2) -> -0.17528 | L25: =INDEX(Embeddings!$C$2:$R$2629,J$11,COLUMN()-2) -> -0.0514 | M25: =INDEX(Embeddings!$C$2:$R$2629,J$11,COLUMN()-2) -> 3.08607 | N25: =INDEX(Embeddings!$C$2:$R$2629,J$11,COLUMN()-2) -> 1.03136 | O25: =INDEX(Embeddings!$C$2:$R$2629,J$11,COLUMN()-2) -> -0.16113 | P25: =INDEX(Embeddings!$C$2:$R$2629,J$11,COLUMN()-2) -> -1.35821 | Q25: =INDEX(Embeddings!$C$2:$R$2629,J$11,COLUMN()-2) -> -0.29553 | R25: =INDEX(Embeddings!$C$2:$R$2629,J$11,COLUMN()-2) -> -1.30229
B26: =K10 -> would | C26: =INDEX(Embeddings!$C$2:$R$2629,K$11,COLUMN()-2) -> -1.41172 | D26: =INDEX(Embeddings!$C$2:$R$2629,K$11,COLUMN()-2) -> 0.07554 | E26: =INDEX(Embeddings!$C$2:$R$2629,K$11,COLUMN()-2) -> 1.95098 | F26: =INDEX(Embeddings!$C$2:$R$2629,K$11,COLUMN()-2) -> 1.14602 | G26: =INDEX(Embeddings!$C$2:$R$2629,K$11,COLUMN()-2) -> -0.13432 | H26: =INDEX(Embeddings!$C$2:$R$2629,K$11,COLUMN()-2) -> -0.98694 | I26: =INDEX(Embeddings!$C$2:$R$2629,K$11,COLUMN()-2) -> 1.75483 | J26: =INDEX(Embeddings!$C$2:$R$2629,K$11,COLUMN()-2) -> -0.87026 | K26: =INDEX(Embeddings!$C$2:$R$2629,K$11,COLUMN()-2) -> 0.58196 | L26: =INDEX(Embeddings!$C$2:$R$2629,K$11,COLUMN()-2) -> 1.0168 | M26: =INDEX(Embeddings!$C$2:$R$2629,K$11,COLUMN()-2) -> 0.63619 | N26: =INDEX(Embeddings!$C$2:$R$2629,K$11,COLUMN()-2) -> 0.24306 | O26: =INDEX(Embeddings!$C$2:$R$2629,K$11,COLUMN()-2) -> 0.92581 | P26: =INDEX(Embeddings!$C$2:$R$2629,K$11,COLUMN()-2) -> 1.38879 | Q26: =INDEX(Embeddings!$C$2:$R$2629,K$11,COLUMN()-2) -> 0.59301 | R26: =INDEX(Embeddings!$C$2:$R$2629,K$11,COLUMN()-2) -> -1.98864
B27: Learned vectors: the model's "meaning" for each word. <unk> (token 1) is all zeros so it contributes nothing.
B29: STEP 4 · ATTENTION: THE MODEL LEARNED THESE SCORES ITSELF
B30: -1.22 | C30: -0.89 | D30: -0.88 | E30: -0.94 | F30: -0.79 | G30: -0.58 | H30: -0.22 | I30: 0.17 | J30: 0.65 | K30: 1.46
B31: =EXP(B30)/SUMPRODUCT(EXP($B$30:$K$30)) -> 0.027503276 | C31: =EXP(C30)/SUMPRODUCT(EXP($B$30:$K$30)) -> 0.03825618 | D31: =EXP(D30)/SUMPRODUCT(EXP($B$30:$K$30)) -> 0.038640661 | E31: =EXP(E30)/SUMPRODUCT(EXP($B$30:$K$30)) -> 0.036390404 | F31: =EXP(F30)/SUMPRODUCT(EXP($B$30:$K$30)) -> 0.042279617 | G31: =EXP(G30)/SUMPRODUCT(EXP($B$30:$K$30)) -> 0.052159436 | H31: =EXP(H30)/SUMPRODUCT(EXP($B$30:$K$30)) -> 0.074761654 | I31: =EXP(I30)/SUMPRODUCT(EXP($B$30:$K$30)) -> 0.11042153 | ... K31: =EXP(K30)/SUMPRODUCT(EXP($B$30:$K$30)) -> 0.40113784
B32: Row 30: raw scores, exactly as gradient descent left them (editable). Row 31: their softmax. Nobody told the model recency matters; it learned the 2.7% -> 40% ramp from the data alone.
B34: STEP 5 · MIX INTO ONE CONTEXT VECTOR (MMULT #1: 1x10 times 10x16 = 1x16)
B35: context c = | C35: {=MMULT(B31:K31,C17:R26)} -> -0.62842094 | D35: -0.24546148 | E35: 1.257038 | F35: 0.10870256 | G35: -0.39605677 | H35: -0.45676224 | I35: 0.35345643 | J35: -0.35777534 | K35: 0.4239627 | L35: 0.4227204 | M35: 0.91069347 | N35: 0.28775189 | O35: 0.22272053 | P35: 0.26645162 | Q35: 0.29177747 | R35: -1.2777709
B37: STEP 6 · HIDDEN LAYER (MMULT #2: c times the 16x16 matrix, then TANH)
B38: c x W = | C38: {=MMULT(C35:R35,'Hidden Weights'!$C$3:$R$18)} -> -1.2949063 | D38: 9.0517968 | E38: 5.2510643 | F38: 0.72483897 | G38: -6.1625198 | H38: -3.9246647 | I38: 0.37511529 | J38: -21.316641 | K38: 4.4904264 | L38: 8.1100411 | M38: 4.5693928 | N38: -1.530197 | O38: 13.118653 | P38: 4.8262008 | Q38: -5.7804551 | R38: -3.3920319
B39: h = TANH: | C39: =TANH(C38) -> -0.8604061 | D39: =TANH(D38) -> 0.99999997 | E39: =TANH(E38) -> 0.99994505 | F39: =TANH(F38) -> 0.61989773 | G39: =TANH(G38) -> -0.99999112 | H39: =TANH(H38) -> -0.99922028 | I39: =TANH(I38) -> 0.35845788 | J39: =TANH(J38) -> -1 | ... R39: =TANH(R38) -> -0.99773922
B40: TANH squashes into -1..1: the nonlinearity that makes this a neural network instead of one big matrix.
B42: STEP 7 · SCORE EVERY WORD (MMULT #3, on the Prediction tab)
B43: One array formula multiplies the 2627 x 16 Output Weights by TRANSPOSE(h): 2628 scores at once.
B44: Softmax with temperature turns scores into probabilities. See the Prediction tab for every word's score.
B45: temperature | C45: 1 | D45: <- editable. 0.3 = confident, 3.0 = chaotic.
B47: STEP 8 · THE PREDICTION
...

Sheet Training Example
B1: ONE REAL TRAINING EXAMPLE, LIVE
B2: Training data is just the book, cut into 10-word windows plus the word that came next. Here is one of the 26,673.
B4: THE EXAMPLE (yellow = editable; the default is a real passage from chapter 1)
B5: w1 | C5: w2 | D5: w3 | E5: w4 | F5: w5 | G5: w6 | H5: w7 | I5: w8 | J5: w9 | K5: w10
B6: there | C6: was | D6: nothing | E6: so | F6: very | G6: remarkable | H6: in | I6: that | J6: nor | K6: did
B7: target (the word that ACTUALLY came next in the book):
B8: alice | C8: <- "...nor did Alice think it so very much out of the way..."
B10: FORWARD PASS (identical math to the Prompt tab)
B11: =IFERROR(MATCH(TRIM(SUBSTITUTE(SUBSTITUTE(SUBSTITUTE(SUBSTITUTE(LOWER(B6),".",""),",",""),"!",""),"?","")),Vocabulary!$B$2:$B$2629,0),1) -> 57 | C11: =IFERROR(MATCH(TRIM(SUBSTITUTE(SUBSTITUTE(SUBSTITUTE(SUBSTITUTE(LOWER(C6),".",""),",",""),"!",""),"?","")),Vocabulary!$B$2:$B$2629,0),1) -> 14 | D11: =IFERROR(MATCH(TRIM(SUBSTITUTE(SUBSTITUTE(SUBSTITUTE(SUBSTITUTE(LOWER(D6),".",""),",",""),"!",""),"?","")),Vocabulary!$B$2:$B$2629,0),1) -> 131 | E11: =IFERROR(MATCH(TRIM(SUBSTITUTE(SUBSTITUTE(SUBSTITUTE(SUBSTITUTE(LOWER(E6),".",""),",",""),"!",""),"?","")),Vocabulary!$B$2:$B$2629,0),1) -> 25 | F11: =IFERROR(MATCH(TRIM(SUBSTITUTE(SUBSTITUTE(SUBSTITUTE(SUBSTITUTE(LOWER(F6),".",""),",",""),"!",""),"?","")),Vocabulary!$B$2:$B$2629,0),1) -> 28 | G11: =IFERROR(MATCH(TRIM(SUBSTITUTE(SUBSTITUTE(SUBSTITUTE(SUBSTITUTE(LOWER(G6),".",""),",",""),"!",""),"?","")),Vocabulary!$B$2:$B$2629,0),1) -> 1083 | H11: =IFERROR(MATCH(TRIM(SUBSTITUTE(SUBSTITUTE(SUBSTITUTE(SUBSTITUTE(LOWER(H6),".",""),",",""),"!",""),"?","")),Vocabulary!$B$2:$B$2629,0),1) -> 12 | I11: =IFERROR(MATCH(TRIM(SUBSTITUTE(SUBSTITUTE(SUBSTITUTE(SUBSTITUTE(LOWER(I6),".",""),",",""),"!",""),"?","")),Vocabulary!$B$2:$B$2629,0),1) -> 15 | ... K11: =IFERROR(MATCH(TRIM(SUBSTITUTE(SUBSTITUTE(SUBSTITUTE(SUBSTITUTE(LOWER(K6),".",""),",",""),"!",""),"?","")),Vocabulary!$B$2:$B$2629,0),1) -> 67
B13: target token ID: | C13: =IFERROR(MATCH(TRIM(SUBSTITUTE(SUBSTITUTE(SUBSTITUTE(SUBSTITUTE(LOWER(B8),".",""),",",""),"!",""),"?","")),Vocabulary!$B$2:$B$2629,0),1) -> 11
B15: token | C15: d1 | D15: d2 | E15: d3 | F15: d4 | G15: d5 | H15: d6 | I15: d7 | J15: d8 | K15: d9 | L15: d10 | M15: d11 | N15: d12 | O15: d13 | P15: d14 | Q15: d15 | R15: d16
B16: =B6 -> there | C16: =INDEX(Embeddings!$C$2:$R$2629,B$11,COLUMN()-2) -> -0.40301 | D16: =INDEX(Embeddings!$C$2:$R$2629,B$11,COLUMN()-2) -> -1.50844 | E16: =INDEX(Embeddings!$C$2:$R$2629,B$11,COLUMN()-2) -> 0.04131 | F16: =INDEX(Embeddings!$C$2:$R$2629,B$11,COLUMN()-2) -> -1.50042 | G16: =INDEX(Embeddings!$C$2:$R$2629,B$11,COLUMN()-2) -> -0.7171 | H16: =INDEX(Embeddings!$C$2:$R$2629,B$11,COLUMN()-2) -> 0.51543 | I16: =INDEX(Embeddings!$C$2:$R$2629,B$11,COLUMN()-2) -> 0.76644 | J16: =INDEX(Embeddings!$C$2:$R$2629,B$11,COLUMN()-2) -> 0.10743 | K16: =INDEX(Embeddings!$C$2:$R$2629,B$11,COLUMN()-2) -> 0.23841 | L16: =INDEX(Embeddings!$C$2:$R$2629,B$11,COLUMN()-2) -> 0.20922 | M16: =INDEX(Embeddings!$C$2:$R$2629,B$11,COLUMN()-2) -> -0.21415 | N16: =INDEX(Embeddings!$C$2:$R$2629,B$11,COLUMN()-2) -> 0.48935 | O16: =INDEX(Embeddings!$C$2:$R$2629,B$11,COLUMN()-2) -> -1.17285 | P16: =INDEX(Embeddings!$C$2:$R$2629,B$11,COLUMN()-2) -> -0.1599 | Q16: =INDEX(Embeddings!$C$2:$R$2629,B$11,COLUMN()-2) -> -0.50172 | R16: =INDEX(Embeddings!$C$2:$R$2629,B$11,COLUMN()-2) -> -1.22955
B17: =C6 -> was | C17: =INDEX(Embeddings!$C$2:$R$2629,C$11,COLUMN()-2) -> 1.01562 | D17: =INDEX(Embeddings!$C$2:$R$2629,C$11,COLUMN()-2) -> 0.2853 | E17: =INDEX(Embeddings!$C$2:$R$2629,C$11,COLUMN()-2) -> 1.23108 | F17: =INDEX(Embeddings!$C$2:$R$2629,C$11,COLUMN()-2) -> 1.28132 | G17: =INDEX(Embeddings!$C$2:$R$2629,C$11,COLUMN()-2) -> 0.15807 | H17: =INDEX(Embeddings!$C$2:$R$2629,C$11,COLUMN()-2) -> -0.50829 | I17: =INDEX(Embeddings!$C$2:$R$2629,C$11,COLUMN()-2) -> 0.68136 | J17: =INDEX(Embeddings!$C$2:$R$2629,C$11,COLUMN()-2) -> -0.36745 | K17: =INDEX(Embeddings!$C$2:$R$2629,C$11,COLUMN()-2) -> -0.2726 | L17: =INDEX(Embeddings!$C$2:$R$2629,C$11,COLUMN()-2) -> 0.58087 | M17: =INDEX(Embeddings!$C$2:$R$2629,C$11,COLUMN()-2) -> -0.71129 | N17: =INDEX(Embeddings!$C$2:$R$2629,C$11,COLUMN()-2) -> 0.19566 | O17: =INDEX(Embeddings!$C$2:$R$2629,C$11,COLUMN()-2) -> -0.06524 | P17: =INDEX(Embeddings!$C$2:$R$2629,C$11,COLUMN()-2) -> 0.17833 | Q17: =INDEX(Embeddings!$C$2:$R$2629,C$11,COLUMN()-2) -> -0.78746 | R17: =INDEX(Embeddings!$C$2:$R$2629,C$11,COLUMN()-2) -> 0.36907
B18: =D6 -> nothing | C18: =INDEX(Embeddings!$C$2:$R$2629,D$11,COLUMN()-2) -> 0.24121 | D18: =INDEX(Embeddings!$C$2:$R$2629,D$11,COLUMN()-2) -> -1.14959 | E18: =INDEX(Embeddings!$C$2:$R$2629,D$11,COLUMN()-2) -> 1.20992 | F18: =INDEX(Embeddings!$C$2:$R$2629,D$11,COLUMN()-2) -> 0.01043 | G18: =INDEX(Embeddings!$C$2:$R$2629,D$11,COLUMN()-2) -> -0.54161 | H18: =INDEX(Embeddings!$C$2:$R$2629,D$11,COLUMN()-2) -> -0.13122 | I18: =INDEX(Embeddings!$C$2:$R$2629,D$11,COLUMN()-2) -> -0.06199 | J18: =INDEX(Embeddings!$C$2:$R$2629,D$11,COLUMN()-2) -> 1.41663 | K18: =INDEX(Embeddings!$C$2:$R$2629,D$11,COLUMN()-2) -> 0.48902 | L18: =INDEX(Embeddings!$C$2:$R$2629,D$11,COLUMN()-2) -> -0.91963 | M18: =INDEX(Embeddings!$C$2:$R$2629,D$11,COLUMN()-2) -> 0.0858 | N18: =INDEX(Embeddings!$C$2:$R$2629,D$11,COLUMN()-2) -> -1.20417 | O18: =INDEX(Embeddings!$C$2:$R$2629,D$11,COLUMN()-2) -> 0.02562 | P18: =INDEX(Embeddings!$C$2:$R$2629,D$11,COLUMN()-2) -> -0.3223 | Q18: =INDEX(Embeddings!$C$2:$R$2629,D$11,COLUMN()-2) -> 0.33102 | R18: =INDEX(Embeddings!$C$2:$R$2629,D$11,COLUMN()-2) -> -0.30852
B19: =E6 -> so | C19: =INDEX(Embeddings!$C$2:$R$2629,E$11,COLUMN()-2) -> -0.42381 | D19: =INDEX(Embeddings!$C$2:$R$2629,E$11,COLUMN()-2) -> 0.59214 | E19: =INDEX(Embeddings!$C$2:$R$2629,E$11,COLUMN()-2) -> -0.10978 | F19: =INDEX(Embeddings!$C$2:$R$2629,E$11,COLUMN()-2) -> -0.07921 | G19: =INDEX(Embeddings!$C$2:$R$2629,E$11,COLUMN()-2) -> 0.13794 | H19: =INDEX(Embeddings!$C$2:$R$2629,E$11,COLUMN()-2) -> -0.24033 | I19: =INDEX(Embeddings!$C$2:$R$2629,E$11,COLUMN()-2) -> 0.51734 | J19: =INDEX(Embeddings!$C$2:$R$2629,E$11,COLUMN()-2) -> -1.13292 | K19: =INDEX(Embeddings!$C$2:$R$2629,E$11,COLUMN()-2) -> -0.56784 | L19: =INDEX(Embeddings!$C$2:$R$2629,E$11,COLUMN()-2) -> 0.04557 | M19: =INDEX(Embeddings!$C$2:$R$2629,E$11,COLUMN()-2) -> -0.13465 | N19: =INDEX(Embeddings!$C$2:$R$2629,E$11,COLUMN()-2) -> 0.92854 | O19: =INDEX(Embeddings!$C$2:$R$2629,E$11,COLUMN()-2) -> 0.19515 | P19: =INDEX(Embeddings!$C$2:$R$2629,E$11,COLUMN()-2) -> -0.39203 | Q19: =INDEX(Embeddings!$C$2:$R$2629,E$11,COLUMN()-2) -> -0.06775 | R19: =INDEX(Embeddings!$C$2:$R$2629,E$11,COLUMN()-2) -> -0.99232
B20: =F6 -> very | C20: =INDEX(Embeddings!$C$2:$R$2629,F$11,COLUMN()-2) -> -0.37809 | D20: =INDEX(Embeddings!$C$2:$R$2629,F$11,COLUMN()-2) -> 0.4452 | E20: =INDEX(Embeddings!$C$2:$R$2629,F$11,COLUMN()-2) -> -0.5399 | F20: =INDEX(Embeddings!$C$2:$R$2629,F$11,COLUMN()-2) -> 0.13263 | G20: =INDEX(Embeddings!$C$2:$R$2629,F$11,COLUMN()-2) -> 0.44191 | H20: =INDEX(Embeddings!$C$2:$R$2629,F$11,COLUMN()-2) -> 0.90927 | I20: =INDEX(Embeddings!$C$2:$R$2629,F$11,COLUMN()-2) -> -1.64907 | J20: =INDEX(Embeddings!$C$2:$R$2629,F$11,COLUMN()-2) -> -0.17889 | K20: =INDEX(Embeddings!$C$2:$R$2629,F$11,COLUMN()-2) -> -0.33347 | L20: =INDEX(Embeddings!$C$2:$R$2629,F$11,COLUMN()-2) -> -1.15924 | M20: =INDEX(Embeddings!$C$2:$R$2629,F$11,COLUMN()-2) -> 0.12384 | N20: =INDEX(Embeddings!$C$2:$R$2629,F$11,COLUMN()-2) -> 0.8915 | O20: =INDEX(Embeddings!$C$2:$R$2629,F$11,COLUMN()-2) -> 0.25877 | P20: =INDEX(Embeddings!$C$2:$R$2629,F$11,COLUMN()-2) -> -0.23541 | Q20: =INDEX(Embeddings!$C$2:$R$2629,F$11,COLUMN()-2) -> -0.90271 | R20: =INDEX(Embeddings!$C$2:$R$2629,F$11,COLUMN()-2) -> -0.46625
B21: =G6 -> remarkable | C21: =INDEX(Embeddings!$C$2:$R$2629,G$11,COLUMN()-2) -> 1.93622 | D21: =INDEX(Embeddings!$C$2:$R$2629,G$11,COLUMN()-2) -> -0.68936 | E21: =INDEX(Embeddings!$C$2:$R$2629,G$11,COLUMN()-2) -> 0.54856 | F21: =INDEX(Embeddings!$C$2:$R$2629,G$11,COLUMN()-2) -> -0.48967 | G21: =INDEX(Embeddings!$C$2:$R$2629,G$11,COLUMN()-2) -> -0.28349 | H21: =INDEX(Embeddings!$C$2:$R$2629,G$11,COLUMN()-2) -> 0.76515 | I21: =INDEX(Embeddings!$C$2:$R$2629,G$11,COLUMN()-2) -> 0.16178 | J21: =INDEX(Embeddings!$C$2:$R$2629,G$11,COLUMN()-2) -> 4.61985 | K21: =INDEX(Embeddings!$C$2:$R$2629,G$11,COLUMN()-2) -> -0.86611 | L21: =INDEX(Embeddings!$C$2:$R$2629,G$11,COLUMN()-2) -> 0.1819 | M21: =INDEX(Embeddings!$C$2:$R$2629,G$11,COLUMN()-2) -> -2.30708 | N21: =INDEX(Embeddings!$C$2:$R$2629,G$11,COLUMN()-2) -> -2.1742 | O21: =INDEX(Embeddings!$C$2:$R$2629,G$11,COLUMN()-2) -> -4.03665 | P21: =INDEX(Embeddings!$C$2:$R$2629,G$11,COLUMN()-2) -> -1.90836 | Q21: =INDEX(Embeddings!$C$2:$R$2629,G$11,COLUMN()-2) -> 0.5517 | R21: =INDEX(Embeddings!$C$2:$R$2629,G$11,COLUMN()-2) -> -0.12093
B22: =H6 -> in | C22: =INDEX(Embeddings!$C$2:$R$2629,H$11,COLUMN()-2) -> 0.24412 | D22: =INDEX(Embeddings!$C$2:$R$2629,H$11,COLUMN()-2) -> -0.72087 | E22: =INDEX(Embeddings!$C$2:$R$2629,H$11,COLUMN()-2) -> 1.28378 | F22: =INDEX(Embeddings!$C$2:$R$2629,H$11,COLUMN()-2) -> 0.03207 | G22: =INDEX(Embeddings!$C$2:$R$2629,H$11,COLUMN()-2) -> -0.46749 | H22: =INDEX(Embeddings!$C$2:$R$2629,H$11,COLUMN()-2) -> 0.24337 | I22: =INDEX(Embeddings!$C$2:$R$2629,H$11,COLUMN()-2) -> 1.59235 | J22: =INDEX(Embeddings!$C$2:$R$2629,H$11,COLUMN()-2) -> -0.97802 | K22: =INDEX(Embeddings!$C$2:$R$2629,H$11,COLUMN()-2) -> -0.1698 | L22: =INDEX(Embeddings!$C$2:$R$2629,H$11,COLUMN()-2) -> -0.89184 | M22: =INDEX(Embeddings!$C$2:$R$2629,H$11,COLUMN()-2) -> 0.03846 | N22: =INDEX(Embeddings!$C$2:$R$2629,H$11,COLUMN()-2) -> 0.41749 | O22: =INDEX(Embeddings!$C$2:$R$2629,H$11,COLUMN()-2) -> 0.25886 | P22: =INDEX(Embeddings!$C$2:$R$2629,H$11,COLUMN()-2) -> 0.95634 | Q22: =INDEX(Embeddings!$C$2:$R$2629,H$11,COLUMN()-2) -> -1.33422 | R22: =INDEX(Embeddings!$C$2:$R$2629,H$11,COLUMN()-2) -> 0.60227 | U22: max logit | V22: =MAX(V24:V2651) -> 16.16066 | W22: sum of exp | X22: =SUM(W24:W2651) -> 3.6070062
B23: =I6 -> that | C23: =INDEX(Embeddings!$C$2:$R$2629,I$11,COLUMN()-2) -> -0.26994 | D23: =INDEX(Embeddings!$C$2:$R$2629,I$11,COLUMN()-2) -> -0.27285 | E23: =INDEX(Embeddings!$C$2:$R$2629,I$11,COLUMN()-2) -> -0.71564 | F23: =INDEX(Embeddings!$C$2:$R$2629,I$11,COLUMN()-2) -> -0.61836 | G23: =INDEX(Embeddings!$C$2:$R$2629,I$11,COLUMN()-2) -> -0.45482 | H23: =INDEX(Embeddings!$C$2:$R$2629,I$11,COLUMN()-2) -> -0.23998 | I23: =INDEX(Embeddings!$C$2:$R$2629,I$11,COLUMN()-2) -> -0.37378 | J23: =INDEX(Embeddings!$C$2:$R$2629,I$11,COLUMN()-2) -> -0.16345 | K23: =INDEX(Embeddings!$C$2:$R$2629,I$11,COLUMN()-2) -> -0.42537 | L23: =INDEX(Embeddings!$C$2:$R$2629,I$11,COLUMN()-2) -> -0.57902 | M23: =INDEX(Embeddings!$C$2:$R$2629,I$11,COLUMN()-2) -> 0.90195 | N23: =INDEX(Embeddings!$C$2:$R$2629,I$11,COLUMN()-2) -> 0.24819 | O23: =INDEX(Embeddings!$C$2:$R$2629,I$11,COLUMN()-2) -> -0.14958 | P23: =INDEX(Embeddings!$C$2:$R$2629,I$11,COLUMN()-2) -> 0.18556 | Q23: =INDEX(Embeddings!$C$2:$R$2629,I$11,COLUMN()-2) -> -0.20946 | R23: =INDEX(Embeddings!$C$2:$R$2629,I$11,COLUMN()-2) -> -0.5086 | T23: ID | U23: Word | V23: Logit | W23: EXP(L-max) | X23: p | Y23: y (truth)
B24: =J6 -> nor | C24: =INDEX(Embeddings!$C$2:$R$2629,J$11,COLUMN()-2) -> -1.15119 | D24: =INDEX(Embeddings!$C$2:$R$2629,J$11,COLUMN()-2) -> -2.00911 | E24: =INDEX(Embeddings!$C$2:$R$2629,J$11,COLUMN()-2) -> 2.3615 | F24: =INDEX(Embeddings!$C$2:$R$2629,J$11,COLUMN()-2) -> 1.08665 | G24: =INDEX(Embeddings!$C$2:$R$2629,J$11,COLUMN()-2) -> 0.57331 | H24: =INDEX(Embeddings!$C$2:$R$2629,J$11,COLUMN()-2) -> -2.75858 | I24: =INDEX(Embeddings!$C$2:$R$2629,J$11,COLUMN()-2) -> 3.22169 | J24: =INDEX(Embeddings!$C$2:$R$2629,J$11,COLUMN()-2) -> -0.88452 | K24: =INDEX(Embeddings!$C$2:$R$2629,J$11,COLUMN()-2) -> -0.22934 | L24: =INDEX(Embeddings!$C$2:$R$2629,J$11,COLUMN()-2) -> 0.11695 | M24: =INDEX(Embeddings!$C$2:$R$2629,J$11,COLUMN()-2) -> -0.33952 | N24: =INDEX(Embeddings!$C$2:$R$2629,J$11,COLUMN()-2) -> 1.22448 | O24: =INDEX(Embeddings!$C$2:$R$2629,J$11,COLUMN()-2) -> -0.41665 | P24: =INDEX(Embeddings!$C$2:$R$2629,J$11,COLUMN()-2) -> 1.03392 | Q24: =INDEX(Embeddings!$C$2:$R$2629,J$11,COLUMN()-2) -> -0.62461 | R24: =INDEX(Embeddings!$C$2:$R$2629,J$11,COLUMN()-2) -> 1.22691 | T24: 1 | U24: =Vocabulary!B2 -> <unk> | V24: {=MMULT('Output Weights'!$C$2:$R$2629,TRANSPOSE($C$32:$R$32))} -> 0 | W24: =EXP(V24-$V$22) -> 9.5832903e-08 | X24: =W24/$X$22 -> 2.6568544e-08 | Y24: =IF(T24=$C$13,1,0) -> 0
B25: =K6 -> did | C25: =INDEX(Embeddings!$C$2:$R$2629,K$11,COLUMN()-2) -> -0.32301 | D25: =INDEX(Embeddings!$C$2:$R$2629,K$11,COLUMN()-2) -> -0.09104 | E25: =INDEX(Embeddings!$C$2:$R$2629,K$11,COLUMN()-2) -> 1.11213 | F25: =INDEX(Embeddings!$C$2:$R$2629,K$11,COLUMN()-2) -> 1.0146 | G25: =INDEX(Embeddings!$C$2:$R$2629,K$11,COLUMN()-2) -> 0.31299 | H25: =INDEX(Embeddings!$C$2:$R$2629,K$11,COLUMN()-2) -> -0.72875 | I25: =INDEX(Embeddings!$C$2:$R$2629,K$11,COLUMN()-2) -> 0.8719 | J25: =INDEX(Embeddings!$C$2:$R$2629,K$11,COLUMN()-2) -> 0.55997 | K25: =INDEX(Embeddings!$C$2:$R$2629,K$11,COLUMN()-2) -> -1.14787 | L25: =INDEX(Embeddings!$C$2:$R$2629,K$11,COLUMN()-2) -> -0.98815 | M25: =INDEX(Embeddings!$C$2:$R$2629,K$11,COLUMN()-2) -> 0.71389 | N25: =INDEX(Embeddings!$C$2:$R$2629,K$11,COLUMN()-2) -> -0.13227 | O25: =INDEX(Embeddings!$C$2:$R$2629,K$11,COLUMN()-2) -> 0.80422 | P25: =INDEX(Embeddings!$C$2:$R$2629,K$11,COLUMN()-2) -> 2.10415 | Q25: =INDEX(Embeddings!$C$2:$R$2629,K$11,COLUMN()-2) -> 1.04718 | R25: =INDEX(Embeddings!$C$2:$R$2629,K$11,COLUMN()-2) -> -1.27802 | T25: 2 | U25: =Vocabulary!B3 -> the | V25: 15.894399 | W25: =EXP(V25-$V$22) -> 0.76623902 | X25: =W25/$X$22 -> 0.21243075 | Y25: =IF(T25=$C$13,1,0) -> 0
B26: learned attention weights (fixed values here; play with them on the Prompt tab): | T26: 3 | U26: =Vocabulary!B4 -> and | V26: 6.0219485 | W26: =EXP(V26-$V$22) -> 3.9519702e-05 | X26: =W26/$X$22 -> 1.0956372e-05 | Y26: =IF(T26=$C$13,1,0) -> 0
B27: 0.0274 | C27: 0.0382 | D27: 0.0384 | E27: 0.0363 | F27: 0.0419 | G27: 0.052 | H27: 0.0748 | I27: 0.1105 | J27: 0.1788 | K27: 0.4016 | T27: 4 | U27: =Vocabulary!B5 -> to | V27: 13.769127 | W27: =EXP(V27-$V$22) -> 0.091489361 | X27: =W27/$X$22 -> 0.025364348 | Y27: =IF(T27=$C$13,1,0) -> 0
T28: 5 | U28: =Vocabulary!B6 -> a | V28: 13.181439 | W28: =EXP(V28-$V$22) -> 0.050832439 | X28: =W28/$X$22 -> 0.014092695 | Y28: =IF(T28=$C$13,1,0) -> 0
B29: context c = | C29: {=MMULT(B27:K27,C16:R25)} -> -0.24064794 | D29: -0.55013674 | E29: 0.98235451 | F29: 0.5212809 | G29: 0.11735243 | H29: -0.73538433 | I29: 1.0067423 | J29: 0.21043195 | K29: -0.62642023 | L29: -0.55147282 | M29: 0.179123 | N29: 0.15711437 | O29: 0.025688028 | P29: 0.98865569 | Q29: 0.14321083 | R29: -0.39831564 | T29: 6 | U29: =Vocabulary!B7 -> she | V29: 8.7207566 | W29: =EXP(V29-$V$22) -> 0.00058734208 | X29: =W29/$X$22 -> 0.00016283368 | Y29: =IF(T29=$C$13,1,0) -> 0
T30: 7 | U30: =Vocabulary!B8 -> it | V30: 16.16066 | W30: =EXP(V30-$V$22) -> 1 | X30: =W30/$X$22 -> 0.27723823 | Y30: =IF(T30=$C$13,1,0) -> 0
B31: c x W = | C31: {=MMULT(C29:R29,'Hidden Weights'!$C$3:$R$18)} -> -8.9178281 | D31: 13.696411 | E31: -3.6590479 | F31: -4.2541123 | G31: -5.0250493 | H31: -11.157479 | I31: -0.74667388 | J31: -3.6617326 | K31: 5.1657708 | L31: -0.63048196 | M31: -1.9880423 | N31: -3.6878053 | O31: 14.928681 | P31: 2.0403137 | Q31: -18.247869 | R31: 1.2985629 | T31: 8 | U31: =Vocabulary!B9 -> of | V31: 2.2627901 | W31: =EXP(V31-$V$22) -> 9.2094116e-07 | X31: =W31/$X$22 -> 2.553201e-07 | Y31: =IF(T31=$C$13,1,0) -> 0
B32: h = TANH: | C32: =TANH(C31) -> -0.99999996 | D32: =TANH(D31) -> 1 | E32: =TANH(E31) -> -0.99867403 | F32: =TANH(F31) -> -0.99959648 | G32: =TANH(G31) -> -0.99991364 | H32: =TANH(H31) -> -1 | I32: =TANH(I31) -> -0.63316045 | J32: =TANH(J31) -> -0.99868113 | ... R32: =TANH(R31) -> 0.86135274 | T32: 9 | U32: =Vocabulary!B10 -> said | V32: 14.71554 | W32: =EXP(V32-$V$22) -> 0.23571788 | X32: =W32/$X$22 -> 0.065350008 | Y32: =IF(T32=$C$13,1,0) -> 0
T33: 10 | U33: =Vocabulary!B11 -> i | V33: 10.500303 | W33: =EXP(V33-$V$22) -> 0.0034812748 | X33: =W33/$X$22 -> 0.00096514245 | Y33: =IF(T33=$C$13,1,0) -> 0
B34: THE LOSS: HOW SURPRISED WAS THE MODEL BY THE TRUTH? | T34: 11 | U34: =Vocabulary!B12 -> alice | V34: 14.110405 | W34: =EXP(V34-$V$22) -> 0.12870213 | X34: =W34/$X$22 -> 0.03568115 | Y34: =IF(T34=$C$13,1,0) -> 1
B35: The tall table at the right (columns T-Y) scores all 2628 words, exactly like the Prediction tab (temperature 1). | T35: 12 | U35: =Vocabulary!B13 -> in | V35: 10.301198 | W35: =EXP(V35-$V$22) -> 0.0028527779 | X35: =W35/$X$22 -> 0.00079089908 | Y35: =IF(T35=$C$13,1,0) -> 0
B36: p(target): probability given to the true word | F36: =INDEX($X$24:$X$2651,$C$13) -> 0.03568115 | T36: 13 | U36: =Vocabulary!B14 -> you | V36: 14.220028 | W36: =EXP(V36-$V$22) -> 0.1436132 | X36: =W36/$X$22 -> 0.03981507 | Y36: =IF(T36=$C$13,1,0) -> 0
B37: LOSS = -LN(p(target)) | F37: =-LN(F36) -> 3.3331327 | T37: 14 | U37: =Vocabulary!B15 -> was | V37: -0.91838449 | W37: =EXP(V37-$V$22) -> 3.8252985e-08 | X37: =W37/$X$22 -> 1.060519e-08 | Y37: =IF(T37=$C$13,1,0) -> 0
B38: the model's own top pick was: | F38: =INDEX($U$24:$U$2651,MATCH(MAX($X$24:$X$2651),$X$24:$X$2651,0)) -> it | T38: 15 | U38: =Vocabulary!B16 -> that | V38: 11.160273 | W38: =EXP(V38-$V$22) -> 0.0067353417 | X38: =W38/$X$22 -> 0.0018672942 | Y38: =IF(T38=$C$13,1,0) -> 0
B39: A perfect model gives p(target)=100% and loss 0. Blind guessing gives p=1/2628, loss 7.87. Training is nothing more than making this one number smaller, averaged over the whole book. When the top pick is not the target, the gradients on the Backpropagation tab are big. | T39: 16 | U39: =Vocabulary!B17 -> as | V39: 11.186643 | W39: =EXP(V39-$V$22) -> 0.0069153125 | X39: =W39/$X$22 -> 0.001917189 | Y39: =IF(T39=$C$13,1,0) -> 0
T40: 17 | U40: =Vocabulary!B18 -> her | V40: 11.683058 | W40: =EXP(V40-$V$22) -> 0.011360624 | X40: =W40/$X$22 -> 0.0031495992 | Y40: =IF(T40=$C$13,1,0) -> 0
B41: Try it: change the target to "computer" (loss explodes: the model can never predict <unk>-adjacent nonsense) or swap the context words and watch loss, h, and every gradient react. | T41: 18 | U41: =Vocabulary!B19 -> at | V41: 12.997749 | W41: =EXP(V41-$V$22) -> 0.042302443 | X41: =W41/$X$22 -> 0.011727854 | Y41: =IF(T41=$C$13,1,0) -> 0
T42: 19 | U42: =Vocabulary!B20 -> on | V42: 8.8878884 | W42: =EXP(V42-$V$22) -> 0.00069418547 | X42: =W42/$X$22 -> 0.00019245475 | Y42: =IF(T42=$C$13,1,0) -> 0
T43: 20 | U43: =Vocabulary!B21 -> all | V43: 11.953017 | W43: =EXP(V43-$V$22) -> 0.014881406 | X43: =W43/$X$22 -> 0.0041256945 | Y43: =IF(T43=$C$13,1,0) -> 0
T44: 21 | U44: =Vocabulary!B22 -> with | V44: 7.8000758 | W44: =EXP(V44-$V$22) -> 0.00023390771 | X44: =W44/$X$22 -> 6.4848158e-05 | Y44: =IF(T44=$C$13,1,0) -> 0
...

Sheet Backpropagation
B1: BACKPROPAGATION: HOW THE WEIGHTS LEARN
B2: The real gradients for the Training Example, live. Change that tab and every number here follows. Chain rule, as spreadsheet formulas.
B4: STEP 1 · THE ERROR SIGNAL: g = p - y, for every word
B5: Take each word's predicted probability p and subtract 1 if it was the true word. That single subtraction IS the
B6: derivative of cross-entropy loss with respect to each logit. Positive g = scored too high; the target alone goes negative.
B7: target ID | C7: ='Training Example'!$C$13 -> 11 | E7: g at the target | G7: =INDEX($V$24:$V$2651,$C$7) -> -0.96431885 | I7: top-pick ID | K7: =MATCH(MAX('Training Example'!$X$24:$X$2651),'Training Example'!$X$24:$X$2651,0) -> 7
B8: The full g column is the tall table at the right (columns T-V).
B10: STEP 2 · GRADIENT OF THE OUTPUT WEIGHTS: dOut(word) = g(word) x h (two example rows)
B11: word | C11: d1 | D11: d2 | E11: d3 | F11: d4 | G11: d5 | H11: d6 | I11: d7 | J11: d8 | K11: d9 | L11: d10 | M11: d11 | N11: d12 | O11: d13 | P11: d14 | Q11: d15 | R11: d16
B12: =INDEX(Vocabulary!$B$2:$B$2629,$C$7)&" (target)" -> alice (target) | C12: =INDEX($V$24:$V$2651,$C$7)*'Training Example'!C$32 -> 0.96431882 | D12: =INDEX($V$24:$V$2651,$C$7)*'Training Example'!D$32 -> -0.96431885 | E12: =INDEX($V$24:$V$2651,$C$7)*'Training Example'!E$32 -> 0.96304019 | F12: =INDEX($V$24:$V$2651,$C$7)*'Training Example'!F$32 -> 0.96392973 | G12: =INDEX($V$24:$V$2651,$C$7)*'Training Example'!G$32 -> 0.96423557 | H12: =INDEX($V$24:$V$2651,$C$7)*'Training Example'!H$32 -> 0.96431885 | I12: =INDEX($V$24:$V$2651,$C$7)*'Training Example'!I$32 -> 0.61056855 | J12: =INDEX($V$24:$V$2651,$C$7)*'Training Example'!J$32 -> 0.96304704 | ... R12: =INDEX($V$24:$V$2651,$C$7)*'Training Example'!R$32 -> -0.83061868
B13: =INDEX(Vocabulary!$B$2:$B$2629,$K$7)&" (top pick)" -> it (top pick) | C13: =INDEX($V$24:$V$2651,$K$7)*'Training Example'!C$32 -> -0.27723822 | D13: =INDEX($V$24:$V$2651,$K$7)*'Training Example'!D$32 -> 0.27723823 | E13: =INDEX($V$24:$V$2651,$K$7)*'Training Example'!E$32 -> -0.27687062 | F13: =INDEX($V$24:$V$2651,$K$7)*'Training Example'!F$32 -> -0.27712636 | G13: =INDEX($V$24:$V$2651,$K$7)*'Training Example'!G$32 -> -0.27721429 | H13: =INDEX($V$24:$V$2651,$K$7)*'Training Example'!H$32 -> -0.27723823 | I13: =INDEX($V$24:$V$2651,$K$7)*'Training Example'!I$32 -> -0.17553628 | J13: =INDEX($V$24:$V$2651,$K$7)*'Training Example'!J$32 -> -0.27687259 | ... R13: =INDEX($V$24:$V$2651,$K$7)*'Training Example'!R$32 -> 0.23879991
B14: Update rule subtracts the gradient, so the target's row (negative g) moves TOWARD h: its score rises next time. Wrong words with positive g get pushed away. Every one of the 2628 output rows gets this treatment at once.
B16: STEP 3 · BACK INTO THE HIDDEN VECTOR: dh = TRANSPOSE(g) MMULT OutputWeights (MMULT #4)
B17: dh = | C17: {=MMULT(TRANSPOSE($V$24:$V$2651),'Output Weights'!$C$2:$R$2629)} -> 0.76347777 | D17: -0.7232794 | E17: -1.1062617 | F17: 0.97937753 | G17: 0.16185461 | H17: -0.26318683 | I17: 0.56859733 | J17: -0.87429065 | K17: 1.076489 | L17: 0.64911169 | M17: -0.0082782768 | N17: 0.31993917 | O17: -0.16284695 | P17: -1.0055916 | Q17: -2.1457023 | R17: 0.24587539
B18: 16 numbers: how much the loss would drop if each hidden activation nudged down. A 1x2628 times 2628x16 MMULT.
B20: STEP 4 · BACK THROUGH TANH: dpre = dh x (1 - h^2)
B21: dpre = | C21: =C17*(1-'Training Example'!C$32^2) -> 5.4818775e-08 | D21: =D17*(1-'Training Example'!D$32^2) -> -3.6713226e-12 | E21: =E17*(1-'Training Example'!E$32^2) -> -0.0029317925 | F21: =F17*(1-'Training Example'!F$32^2) -> 0.00079024154 | G21: =G17*(1-'Training Example'!G$32^2) -> 2.7954078e-05 | H21: =H17*(1-'Training Example'!H$32^2) -> -2.1431922e-10 | I21: =I17*(1-'Training Example'!I$32^2) -> 0.34065112 | J21: =J17*(1-'Training Example'!J$32^2) -> -0.0023046361 | ... R21: =R17*(1-'Training Example'!R$32^2) -> 0.063453419
B22: The derivative of TANH(x) is 1 - TANH(x)^2. A saturated neuron (h near -1 or 1) passes almost no gradient: it has stopped learning. Compare h on the Training Example tab with dpre here.
T23: ID | U23: Word | V23: g = p - y
T24: 1 | U24: =Vocabulary!B2 -> <unk> | V24: ='Training Example'!X24-'Training Example'!Y24 -> 2.6568544e-08
B25: STEP 5 · GRADIENT OF THE HIDDEN WEIGHTS: dW = TRANSPOSE(c) MMULT dpre (MMULT #5: a 16x16 outer product) | T25: 2 | U25: =Vocabulary!B3 -> the | V25: ='Training Example'!X25-'Training Example'!Y25 -> 0.21243075
C26: to d1 | D26: to d2 | E26: to d3 | F26: to d4 | G26: to d5 | H26: to d6 | I26: to d7 | J26: to d8 | K26: to d9 | L26: to d10 | M26: to d11 | N26: to d12 | O26: to d13 | P26: to d14 | Q26: to d15 | R26: to d16 | T26: 3 | U26: =Vocabulary!B4 -> and | V26: ='Training Example'!X26-'Training Example'!Y26 -> 1.0956372e-05
B27: from d1 | C27: {=MMULT(TRANSPOSE('Training Example'!$C$29:$R$29),C21:R21)} -> -1.3192025e-08 | D27: 8.8349622e-13 | E27: 0.00070552983 | F27: -0.00019017 | G27: -6.7270914e-06 | H27: 5.1575479e-11 | I27: -0.081976992 | J27: 0.00055460595 | K27: -3.3766955e-05 | L27: -0.10750307 | M27: 0.00014402824 | N27: -0.00019265432 | O27: 1.6916023e-14 | P27: 0.015816704 | Q27: 0 | R27: -0.015269935 | T27: 4 | U27: =Vocabulary!B5 -> to | V27: ='Training Example'!X27-'Training Example'!Y27 -> 0.025364348
B28: from d2 | C28: -3.0157822e-08 | D28: 2.0197294e-12 | E28: 0.0016128868 | F28: -0.00043474091 | G28: -1.5378565e-05 | H28: 1.1790488e-10 | I28: -0.1874047 | J28: 0.001267865 | K28: -7.719344e-05 | L28: -0.24575896 | M28: 0.00032925785 | N28: -0.00044042022 | O28: 3.867112e-14 | P28: 0.036158008 | Q28: 0 | R28: -0.034908057 | T28: 5 | U28: =Vocabulary!B6 -> a | V28: ='Training Example'!X28-'Training Example'!Y28 -> 0.014092695
B29: from d3 | C29: 5.3851471e-08 | D29: -3.6065403e-12 | E29: -0.0028800596 | F29: 0.00077629734 | G29: 2.7460815e-05 | H29: -2.1053745e-10 | I29: 0.33464017 | J29: -0.0022639697 | K29: 0.00013784086 | L29: 0.43884076 | M29: -0.00058794098 | N29: 0.00078643863 | O29: -6.9053285e-14 | P29: -0.064565734 | Q29: 0 | R29: 0.062333752 | T29: 6 | U29: =Vocabulary!B7 -> she | V29: ='Training Example'!X29-'Training Example'!Y29 -> 0.00016283368
B30: from d4 | C30: 2.857598e-08 | D30: -1.9137903e-12 | E30: -0.0015282874 | F30: 0.00041193782 | G30: 1.4571927e-05 | H30: -1.1172051e-10 | I30: 0.17757492 | J30: -0.0012013628 | K30: 7.3144479e-05 | L30: 0.23286838 | M30: -0.00031198758 | N30: 0.00041731924 | O30: -3.6642738e-14 | P30: -0.034261444 | Q30: 0 | R30: 0.033077055 | T30: 7 | U30: =Vocabulary!B8 -> it | V30: ='Training Example'!X30-'Training Example'!Y30 -> 0.27723823
B31: from d5 | C31: 6.4331165e-09 | D31: -4.3083863e-13 | E31: -0.00034405298 | F31: 9.2736766e-05 | G31: 3.280479e-06 | H31: -2.5150881e-11 | I31: 0.039976237 | J31: -0.00027045465 | K31: 1.646652e-05 | L31: 0.052424079 | M31: -7.0235646e-05 | N31: 9.3948248e-05 | O31: -8.2491309e-15 | P31: -0.0077130463 | Q31: 0 | R31: 0.007446413 | T31: 8 | U31: =Vocabulary!B9 -> of | V31: ='Training Example'!X31-'Training Example'!Y31 -> 2.553201e-07
B32: from d6 | C32: -4.0312868e-08 | D32: 2.6998331e-12 | E32: 0.0021559942 | F32: -0.00058113125 | G32: -2.0556991e-05 | H32: 1.5760699e-10 | I32: -0.2505095 | J32: 0.0016947933 | K32: -0.00010318679 | L32: -0.3285134 | M32: 0.00044012887 | N32: -0.00058872295 | O32: 5.1692849e-14 | P32: 0.048333497 | Q32: 0 | R32: -0.04666265 | T32: 9 | U32: =Vocabulary!B10 -> said | V32: ='Training Example'!X32-'Training Example'!Y32 -> 0.065350008
B33: from d7 | C33: 5.5188378e-08 | D33: -3.6960756e-12 | E33: -0.0029515594 | F33: 0.00079556956 | G33: 2.8142552e-05 | H33: -2.1576422e-10 | I33: 0.34294788 | J33: -0.0023201746 | K33: 0.00014126288 | L33: 0.44973534 | M33: -0.0006025371 | N33: 0.00080596261 | O33: -7.076759e-14 | P33: -0.066168631 | Q33: 0 | R33: 0.063881239 | T33: 10 | U33: =Vocabulary!B11 -> i | V33: ='Training Example'!X33-'Training Example'!Y33 -> 0.00096514245
B34: from d8 | C34: 1.1535622e-08 | D34: -7.7256358e-13 | E34: -0.00061694282 | F34: 0.00016629207 | G34: 5.8824312e-06 | H34: -4.5099612e-11 | I34: 0.071683881 | J34: -0.00048496908 | K34: 2.9527143e-05 | L34: 0.09400488 | M34: -0.00012594391 | N34: 0.00016846445 | O34: -1.479203e-14 | P34: -0.013830744 | Q34: 0 | R34: 0.013352627 | T34: 11 | U34: =Vocabulary!B12 -> alice | V34: ='Training Example'!X34-'Training Example'!Y34 -> -0.96431885
B35: from d9 | C35: -3.433959e-08 | D35: 2.2997907e-12 | E35: 0.0018365341 | F35: -0.00049502329 | G35: -1.7511e-05 | H35: 1.3425389e-10 | I35: -0.21339076 | J35: 0.0014436707 | K35: -8.7897297e-05 | L35: -0.27983658 | M35: 0.00037491366 | N35: -0.00050149011 | O35: 4.4033365e-14 | P35: 0.041171778 | Q35: 0 | R35: -0.039748505 | T35: 12 | U35: =Vocabulary!B13 -> in | V35: ='Training Example'!X35-'Training Example'!Y35 -> 0.00079089908
B36: from d10 | C36: -3.0231064e-08 | D36: 2.0246346e-12 | E36: 0.0016168039 | F36: -0.00043579673 | G36: -1.5415914e-05 | H36: 1.1819122e-10 | I36: -0.18785983 | J36: 0.0012709442 | K36: -7.7380914e-05 | L36: -0.24635582 | M36: 0.0003300575 | N36: -0.00044148983 | O36: 3.8765038e-14 | P36: 0.036245822 | Q36: 0 | R36: -0.034992836 | T36: 13 | U36: =Vocabulary!B14 -> you | V36: ='Training Example'!X36-'Training Example'!Y36 -> 0.03981507
B37: from d11 | C37: 9.8193037e-09 | D37: -6.5761833e-13 | E37: -0.00052515148 | F37: 0.00014155044 | G37: 5.0072184e-06 | H37: -3.8389502e-11 | I37: 0.061018452 | J37: -0.00041281335 | K37: 2.5133971e-05 | L37: 0.08001844 | M37: -0.00010720545 | N37: 0.00014339961 | O37: -1.259121e-14 | P37: -0.011772948 | Q37: 0 | R37: 0.011365967 | T37: 14 | U37: =Vocabulary!B15 -> was | V37: ='Training Example'!X37-'Training Example'!Y37 -> 1.060519e-08
B38: from d12 | C38: 8.6128171e-09 | D38: -5.7681752e-13 | E38: -0.00046062671 | F38: 0.0001241583 | G38: 4.3919872e-06 | H38: -3.3672628e-11 | I38: 0.053521185 | J38: -0.00036209144 | K38: 2.2045789e-05 | L38: 0.070186666 | M38: -9.4033237e-05 | N38: 0.00012578026 | O38: -1.1044142e-14 | P38: -0.010326419 | Q38: 0 | R38: 0.0099694436 | T38: 15 | U38: =Vocabulary!B16 -> that | V38: ='Training Example'!X38-'Training Example'!Y38 -> 0.0018672942
B39: from d13 | C39: 1.4081862e-09 | D39: -9.4309037e-14 | E39: -7.5311967e-05 | F39: 2.0299747e-05 | G39: 7.1808514e-07 | H39: -5.5054381e-12 | I39: 0.0087506556 | J39: -5.9201558e-05 | K39: 3.6044625e-06 | L39: 0.011475444 | M39: -1.5374332e-05 | N39: 2.0564936e-05 | O39: -1.8057053e-15 | P39: -0.0016883583 | Q39: 0 | R39: 0.0016299932 | T39: 16 | U39: =Vocabulary!B17 -> as | V39: ='Training Example'!X39-'Training Example'!Y39 -> 0.001917189
... B42: from d16 | C42: -2.1835176e-08 | D42: 1.4623452e-12 | E42: 0.0011677788 | F42: -0.00031476557 | G42: -1.1134547e-05 | H42: 8.5366698e-11 | I42: -0.13568667 | J42: 0.00091797263 | K42: -5.5890386e-05 | L42: -0.17793692 | M42: 0.00023839265 | N42: -0.00031887756 | O42: 2.7999061e-14 | P42: 0.026179492 | Q42: 0 | R42: -0.025274489 | T42: 19 | U42: =Vocabulary!B20 -> on | V42: ='Training Example'!X42-'Training Example'!Y42 -> 0.00019245475
B43: Cell (i,k) = c_i x dpre_k. The whole chain rule for a 256-weight matrix, in one MMULT. | T43: 20 | U43: =Vocabulary!B21 -> all | V43: ='Training Example'!X43-'Training Example'!Y43 -> 0.0041256945
T44: 21 | U44: =Vocabulary!B22 -> with | V44: ='Training Example'!X44-'Training Example'!Y44 -> 6.4848158e-05
B45: STEP 6 · GRADIENT REACHING THE EMBEDDINGS: dc = dpre MMULT TRANSPOSE(W) (MMULT #6) | T45: 22 | U45: =Vocabulary!B23 -> had | V45: ='Training Example'!X45-'Training Example'!Y45 -> 8.9157736e-07
B46: dc = | C46: {=MMULT(C21:R21,TRANSPOSE('Hidden Weights'!$C$3:$R$18))} -> -0.42869336 | D46: 1.1501728 | E46: -0.23878981 | F46: 1.5725848 | G46: 1.0171912 | H46: 2.614169 | I46: 0.3403641 | J46: 0.73402313 | K46: 4.8252554 | L46: -0.71472583 | M46: -0.14895576 | N46: 3.0501999 | O46: 1.3788189 | P46: 2.2391691 | Q46: 1.1721967 | R46: -1.094938 | T46: 23 | U46: =Vocabulary!B24 -> but | V46: ='Training Example'!X46-'Training Example'!Y46 -> 2.3535965e-05
...

Sheet Gradient Descent Lab
B1: GRADIENT DESCENT LAB: TEACH THE MODEL A WORD
B2: Pick a context and the word you WANT next. Twenty live gradient steps tune the output weights until the model agrees.
B4: THE SETUP (yellow = yours). Default: chapter 8 opens "A large rose-tree stood near the entrance of the garden..."
B5: w1 | C5: w2 | D5: w3 | E5: w4 | F5: w5 | G5: w6 | H5: w7 | I5: w8 | J5: w9 | K5: w10 | AB5: machine room: embeddings (10x16), attention, c, pre, h
B6: a | C6: large | D6: rose | E6: tree | F6: stood | G6: near | H6: the | I6: entrance | J6: of | K6: the
B7: or paste a sentence: | C7: A large rose tree stood near the entrance of the... | M7: =IF($C$7="",0,LEN(TRIM($C$7))-LEN(SUBSTITUTE(TRIM($C$7)," ",""))+1) -> 10
B8: the word you WANT next: | C8: garden | D8: <- the book says "garden". The sentence cell is filled, so it wins; clear it to use the word cells. | AB8: =IF(B$12=1,0,INDEX(Embeddings!$C$2:$R$2629,B$12,1)) -> 0.44645 | AC8: =IF(B$12=1,0,INDEX(Embeddings!$C$2:$R$2629,B$12,2)) -> 0.35822 | AD8: =IF(B$12=1,0,INDEX(Embeddings!$C$2:$R$2629,B$12,3)) -> -0.33882 | AE8: =IF(B$12=1,0,INDEX(Embeddings!$C$2:$R$2629,B$12,4)) -> 0.46646 | AF8: =IF(B$12=1,0,INDEX(Embeddings!$C$2:$R$2629,B$12,5)) -> -0.49398 | AG8: =IF(B$12=1,0,INDEX(Embeddings!$C$2:$R$2629,B$12,6)) -> -0.35397 | AH8: =IF(B$12=1,0,INDEX(Embeddings!$C$2:$R$2629,B$12,7)) -> -1.67177 | AI8: =IF(B$12=1,0,INDEX(Embeddings!$C$2:$R$2629,B$12,8)) -> -1.32692 | AJ8: =IF(B$12=1,0,INDEX(Embeddings!$C$2:$R$2629,B$12,9)) -> -0.02545 | AK8: =IF(B$12=1,0,INDEX(Embeddings!$C$2:$R$2629,B$12,10)) -> 0.24869 | AL8: =IF(B$12=1,0,INDEX(Embeddings!$C$2:$R$2629,B$12,11)) -> 0.63082 | AM8: =IF(B$12=1,0,INDEX(Embeddings!$C$2:$R$2629,B$12,12)) -> -0.58007 | AN8: =IF(B$12=1,0,INDEX(Embeddings!$C$2:$R$2629,B$12,13)) -> -0.04389 | AO8: =IF(B$12=1,0,INDEX(Embeddings!$C$2:$R$2629,B$12,14)) -> 0.52169 | AP8: =IF(B$12=1,0,INDEX(Embeddings!$C$2:$R$2629,B$12,15)) -> -0.25329 | AQ8: =IF(B$12=1,0,INDEX(Embeddings!$C$2:$R$2629,B$12,16)) -> 1.71116
AB9: =IF(C$12=1,0,INDEX(Embeddings!$C$2:$R$2629,C$12,1)) -> 0.84415 | AC9: =IF(C$12=1,0,INDEX(Embeddings!$C$2:$R$2629,C$12,2)) -> 0.91441 | AD9: =IF(C$12=1,0,INDEX(Embeddings!$C$2:$R$2629,C$12,3)) -> 0.0203 | AE9: =IF(C$12=1,0,INDEX(Embeddings!$C$2:$R$2629,C$12,4)) -> -1.36892 | AF9: =IF(C$12=1,0,INDEX(Embeddings!$C$2:$R$2629,C$12,5)) -> -0.93301 | AG9: =IF(C$12=1,0,INDEX(Embeddings!$C$2:$R$2629,C$12,6)) -> 1.08527 | AH9: =IF(C$12=1,0,INDEX(Embeddings!$C$2:$R$2629,C$12,7)) -> 0.00119 | AI9: =IF(C$12=1,0,INDEX(Embeddings!$C$2:$R$2629,C$12,8)) -> 0.50904 | AJ9: =IF(C$12=1,0,INDEX(Embeddings!$C$2:$R$2629,C$12,9)) -> -0.96211 | AK9: =IF(C$12=1,0,INDEX(Embeddings!$C$2:$R$2629,C$12,10)) -> 0.30132 | AL9: =IF(C$12=1,0,INDEX(Embeddings!$C$2:$R$2629,C$12,11)) -> -0.24446 | AM9: =IF(C$12=1,0,INDEX(Embeddings!$C$2:$R$2629,C$12,12)) -> -0.5436 | AN9: =IF(C$12=1,0,INDEX(Embeddings!$C$2:$R$2629,C$12,13)) -> -0.61356 | AO9: =IF(C$12=1,0,INDEX(Embeddings!$C$2:$R$2629,C$12,14)) -> 0.13765 | AP9: =IF(C$12=1,0,INDEX(Embeddings!$C$2:$R$2629,C$12,15)) -> -0.6154 | AQ9: =IF(C$12=1,0,INDEX(Embeddings!$C$2:$R$2629,C$12,16)) -> 0.10653
B10: FORWARD PASS (frozen model): the context becomes a hidden vector h | AB10: =IF(D$12=1,0,INDEX(Embeddings!$C$2:$R$2629,D$12,1)) -> -2.65445 | AC10: =IF(D$12=1,0,INDEX(Embeddings!$C$2:$R$2629,D$12,2)) -> 0.69373 | AD10: =IF(D$12=1,0,INDEX(Embeddings!$C$2:$R$2629,D$12,3)) -> -0.11834 | AE10: =IF(D$12=1,0,INDEX(Embeddings!$C$2:$R$2629,D$12,4)) -> 2.38321 | AF10: =IF(D$12=1,0,INDEX(Embeddings!$C$2:$R$2629,D$12,5)) -> -0.39587 | AG10: =IF(D$12=1,0,INDEX(Embeddings!$C$2:$R$2629,D$12,6)) -> -2.69759 | AH10: =IF(D$12=1,0,INDEX(Embeddings!$C$2:$R$2629,D$12,7)) -> 0.59131 | AI10: =IF(D$12=1,0,INDEX(Embeddings!$C$2:$R$2629,D$12,8)) -> -0.00366 | AJ10: =IF(D$12=1,0,INDEX(Embeddings!$C$2:$R$2629,D$12,9)) -> -1.11391 | AK10: =IF(D$12=1,0,INDEX(Embeddings!$C$2:$R$2629,D$12,10)) -> -0.04272 | AL10: =IF(D$12=1,0,INDEX(Embeddings!$C$2:$R$2629,D$12,11)) -> 1.4403 | AM10: =IF(D$12=1,0,INDEX(Embeddings!$C$2:$R$2629,D$12,12)) -> 2.71419 | AN10: =IF(D$12=1,0,INDEX(Embeddings!$C$2:$R$2629,D$12,13)) -> -0.33637 | AO10: =IF(D$12=1,0,INDEX(Embeddings!$C$2:$R$2629,D$12,14)) -> 1.35974 | AP10: =IF(D$12=1,0,INDEX(Embeddings!$C$2:$R$2629,D$12,15)) -> 1.64899 | AQ10: =IF(D$12=1,0,INDEX(Embeddings!$C$2:$R$2629,D$12,16)) -> -0.47884
B11: =IF($C$7="",TRIM(SUBSTITUTE(SUBSTITUTE(SUBSTITUTE(SUBSTITUTE(LOWER(B6),".",""),",",""),"!",""),"?","")),IF($M$7-10+1<1,"",TRIM(SUBSTITUTE(SUBSTITUTE(SUBSTITUTE(SUBSTITUTE(LOWER(TRIM(MID(SUBSTITUTE(TRIM($C$7)," ",REPT(" ",LEN($C$7))),($M$7-10+1-1)*LEN($C$7)+1,LEN($C$7)))),".",""),",",""),"!",""),"?","")))) -> a | C11: =IF($C$7="",TRIM(SUBSTITUTE(SUBSTITUTE(SUBSTITUTE(SUBSTITUTE(LOWER(C6),".",""),",",""),"!",""),"?","")),IF($M$7-10+2<1,"",TRIM(SUBSTITUTE(SUBSTITUTE(SUBSTITUTE(SUBSTITUTE(LOWER(TRIM(MID(SUBSTITUTE(TRIM($C$7)," ",REPT(" ",LEN($C$7))),($M$7-10+2-1)*LEN($C$7)+1,LEN($C$7)))),".",""),",",""),"!",""),"?","")))) -> large | D11: =IF($C$7="",TRIM(SUBSTITUTE(SUBSTITUTE(SUBSTITUTE(SUBSTITUTE(LOWER(D6),".",""),",",""),"!",""),"?","")),IF($M$7-10+3<1,"",TRIM(SUBSTITUTE(SUBSTITUTE(SUBSTITUTE(SUBSTITUTE(LOWER(TRIM(MID(SUBSTITUTE(TRIM($C$7)," ",REPT(" ",LEN($C$7))),($M$7-10+3-1)*LEN($C$7)+1,LEN($C$7)))),".",""),",",""),"!",""),"?","")))) -> rose | E11: =IF($C$7="",TRIM(SUBSTITUTE(SUBSTITUTE(SUBSTITUTE(SUBSTITUTE(LOWER(E6),".",""),",",""),"!",""),"?","")),IF($M$7-10+4<1,"",TRIM(SUBSTITUTE(SUBSTITUTE(SUBSTITUTE(SUBSTITUTE(LOWER(TRIM(MID(SUBSTITUTE(TRIM($C$7)," ",REPT(" ",LEN($C$7))),($M$7-10+4-1)*LEN($C$7)+1,LEN($C$7)))),".",""),",",""),"!",""),"?","")))) -> tree | F11: =IF($C$7="",TRIM(SUBSTITUTE(SUBSTITUTE(SUBSTITUTE(SUBSTITUTE(LOWER(F6),".",""),",",""),"!",""),"?","")),IF($M$7-10+5<1,"",TRIM(SUBSTITUTE(SUBSTITUTE(SUBSTITUTE(SUBSTITUTE(LOWER(TRIM(MID(SUBSTITUTE(TRIM($C$7)," ",REPT(" ",LEN($C$7))),($M$7-10+5-1)*LEN($C$7)+1,LEN($C$7)))),".",""),",",""),"!",""),"?","")))) -> stood | G11: =IF($C$7="",TRIM(SUBSTITUTE(SUBSTITUTE(SUBSTITUTE(SUBSTITUTE(LOWER(G6),".",""),",",""),"!",""),"?","")),IF($M$7-10+6<1,"",TRIM(SUBSTITUTE(SUBSTITUTE(SUBSTITUTE(SUBSTITUTE(LOWER(TRIM(MID(SUBSTITUTE(TRIM($C$7)," ",REPT(" ",LEN($C$7))),($M$7-10+6-1)*LEN($C$7)+1,LEN($C$7)))),".",""),",",""),"!",""),"?","")))) -> near | H11: =IF($C$7="",TRIM(SUBSTITUTE(SUBSTITUTE(SUBSTITUTE(SUBSTITUTE(LOWER(H6),".",""),",",""),"!",""),"?","")),IF($M$7-10+7<1,"",TRIM(SUBSTITUTE(SUBSTITUTE(SUBSTITUTE(SUBSTITUTE(LOWER(TRIM(MID(SUBSTITUTE(TRIM($C$7)," ",REPT(" ",LEN($C$7))),($M$7-10+7-1)*LEN($C$7)+1,LEN($C$7)))),".",""),",",""),"!",""),"?","")))) -> the | I11: =IF($C$7="",TRIM(SUBSTITUTE(SUBSTITUTE(SUBSTITUTE(SUBSTITUTE(LOWER(I6),".",""),",",""),"!",""),"?","")),IF($M$7-10+8<1,"",TRIM(SUBSTITUTE(SUBSTITUTE(SUBSTITUTE(SUBSTITUTE(LOWER(TRIM(MID(SUBSTITUTE(TRIM($C$7)," ",REPT(" ",LEN($C$7))),($M$7-10+8-1)*LEN($C$7)+1,LEN($C$7)))),".",""),",",""),"!",""),"?","")))) -> entrance | J11: =IF($C$7="",TRIM(SUBSTITUTE(SUBSTITUTE(SUBSTITUTE(SUBSTITUTE(LOWER(J6),".",""),",",""),"!",""),"?","")),IF($M$7-10+9<1,"",TRIM(SUBSTITUTE(SUBSTITUTE(SUBSTITUTE(SUBSTITUTE(LOWER(TRIM(MID(SUBSTITUTE(TRIM($C$7)," ",REPT(" ",LEN($C$7))),($M$7-10+9-1)*LEN($C$7)+1,LEN($C$7)))),".",""),",",""),"!",""),"?","")))) -> of | K11: =IF($C$7="",TRIM(SUBSTITUTE(SUBSTITUTE(SUBSTITUTE(SUBSTITUTE(LOWER(K6),".",""),",",""),"!",""),"?","")),IF($M$7-10+10<1,"",TRIM(SUBSTITUTE(SUBSTITUTE(SUBSTITUTE(SUBSTITUTE(LOWER(TRIM(MID(SUBSTITUTE(TRIM($C$7)," ",REPT(" ",LEN($C$7))),($M$7-10+10-1)*LEN($C$7)+1,LEN($C$7)))),".",""),",",""),"!",""),"?","")))) -> the | AB11: =IF(E$12=1,0,INDEX(Embeddings!$C$2:$R$2629,E$12,1)) -> 0.52705 | AC11: =IF(E$12=1,0,INDEX(Embeddings!$C$2:$R$2629,E$12,2)) -> 0.22724 | AD11: =IF(E$12=1,0,INDEX(Embeddings!$C$2:$R$2629,E$12,3)) -> 0.90916 | AE11: =IF(E$12=1,0,INDEX(Embeddings!$C$2:$R$2629,E$12,4)) -> -2.41625 | AF11: =IF(E$12=1,0,INDEX(Embeddings!$C$2:$R$2629,E$12,5)) -> -0.63509 | AG11: =IF(E$12=1,0,INDEX(Embeddings!$C$2:$R$2629,E$12,6)) -> 0.32985 | AH11: =IF(E$12=1,0,INDEX(Embeddings!$C$2:$R$2629,E$12,7)) -> 0.91204 | AI11: =IF(E$12=1,0,INDEX(Embeddings!$C$2:$R$2629,E$12,8)) -> 0.29357 | AJ11: =IF(E$12=1,0,INDEX(Embeddings!$C$2:$R$2629,E$12,9)) -> -0.84728 | AK11: =IF(E$12=1,0,INDEX(Embeddings!$C$2:$R$2629,E$12,10)) -> -0.42239 | AL11: =IF(E$12=1,0,INDEX(Embeddings!$C$2:$R$2629,E$12,11)) -> -1.2833 | AM11: =IF(E$12=1,0,INDEX(Embeddings!$C$2:$R$2629,E$12,12)) -> 0.78417 | AN11: =IF(E$12=1,0,INDEX(Embeddings!$C$2:$R$2629,E$12,13)) -> -1.01629 | AO11: =IF(E$12=1,0,INDEX(Embeddings!$C$2:$R$2629,E$12,14)) -> -0.21775 | AP11: =IF(E$12=1,0,INDEX(Embeddings!$C$2:$R$2629,E$12,15)) -> 0.19047 | AQ11: =IF(E$12=1,0,INDEX(Embeddings!$C$2:$R$2629,E$12,16)) -> -0.70696
